Workbook

Sheet auscathist
B1: Year | C1: Quarter | D1: FirstDay | E1: LastDay | F1: Event | G1: Type | H1: Location | I1: OriginalCost | J1: NormCost2011 | K1: NormCost2014 | L1: State | M1: Year-Quart | N1: exposure
A2: 1 | B2: 2014 | C2: 2 | D2: 41740 | E2: 41745 | F2: Cyclone | G2: Cyclone | H2: QLD | I2: 8.4 | J2: NA | K2: 8.487 | L2: Queensland | M2: =B2&"-Q"&C2 -> 2014-Q2 | N2: =INDEX(Sheet1!$B$2:$GX$9, MATCH(auscathist!L2, Sheet1!$A$2:$A$9, 0), MATCH(auscathist!M2, Sheet1!$B$1:$GX$1, 0)) -> 4719653
A3: 2 | B3: 2014 | C3: 1 | D3: 41650 | E3: 41653 | F3: Bushfires | G3: Bushfire | H3: Perth | I3: 15 | J3: NA | K3: 15.228 | L3: Western Australia | M3: =B3&"-Q"&C3 -> 2014-Q1 | N3: =INDEX(Sheet1!$B$2:$GX$9, MATCH(auscathist!L3, Sheet1!$A$2:$A$9, 0), MATCH(auscathist!M3, Sheet1!$B$1:$GX$1, 0)) -> 2512556
A4: 3 | B4: 2013 | C4: 4 | D4: 41564 | E4: 41574 | F4: Bushfires | G4: Bushfire | H4: NSW (various locations) | I4: 183.4 | J4: NA | K4: 187.25 | L4: New South Wales | M4: =B4&"-Q"&C4 -> 2013-Q4 | N4: =INDEX(Sheet1!$B$2:$GX$9, MATCH(auscathist!L4, Sheet1!$A$2:$A$9, 0), MATCH(auscathist!M4, Sheet1!$B$1:$GX$1, 0)) -> 7454938
A5: 4 | B5: 2013 | C5: 1 | D5: 41301 | E5: 41304 | F5: Inundation , Storms | G5: Storm | H5: Northern NSW | I5: 121.3 | J5: NA | K5: 126.749 | L5: New South Wales | M5: =B5&"-Q"&C5 -> 2013-Q1 | N5: =INDEX(Sheet1!$B$2:$GX$9, MATCH(auscathist!L5, Sheet1!$A$2:$A$9, 0), MATCH(auscathist!M5, Sheet1!$B$1:$GX$1, 0)) -> 7382957
A6: 5 | B6: 2013 | C6: 1 | D6: 41295 | E6: 41304 | F6: Inundation , Storms | G6: Storm | H6: QLD | I6: 977 | J6: NA | K6: 1020.889 | L6: Queensland | M6: =B6&"-Q"&C6 -> 2013-Q1 | N6: =INDEX(Sheet1!$B$2:$GX$9, MATCH(auscathist!L6, Sheet1!$A$2:$A$9, 0), MATCH(auscathist!M6, Sheet1!$B$1:$GX$1, 0)) -> 4634430
A7: 6 | B7: 2013 | C7: 1 | D7: 41287 | E7: 41293 | F7: Bushfire | G7: Bushfire | H7: Coonabarabran | I7: 35 | J7: NA | K7: 36.572 | L7: New South Wales | M7: =B7&"-Q"&C7 -> 2013-Q1 | N7: =INDEX(Sheet1!$B$2:$GX$9, MATCH(auscathist!L7, Sheet1!$A$2:$A$9, 0), MATCH(auscathist!M7, Sheet1!$B$1:$GX$1, 0)) -> 7382957
A8: 7 | B8: 2013 | C8: 1 | D8: 41278 | E8: 41284 | F8: Bushfire | G8: Bushfire | H8: TAS | I8: 89 | J8: NA | K8: 92.998 | L8: Tasmania | M8: =B8&"-Q"&C8 -> 2013-Q1 | N8: =INDEX(Sheet1!$B$2:$GX$9, MATCH(auscathist!L8, Sheet1!$A$2:$A$9, 0), MATCH(auscathist!M8, Sheet1!$B$1:$GX$1, 0)) -> 512240
A9: 8 | B9: 2012 | C9: 1 | D9: 40963 | E9: 40984 | F9: Flooding | G9: Flood | H9: NSW , VIC | I9: 131.89 | J9: NA | K9: 141.264 | L9: Victoria | M9: =B9&"-Q"&C9 -> 2012-Q1 | N9: =INDEX(Sheet1!$B$2:$GX$9, MATCH(auscathist!L9, Sheet1!$A$2:$A$9, 0), MATCH(auscathist!M9, Sheet1!$B$1:$GX$1, 0)) -> 5625354
A10: 9 | B10: 2012 | C10: 1 | D10: 40932 | E10: 40954 | F10: Flooding | G10: Flood | H10: SW QLD | I10: 131.432 | J10: NA | K10: 140.773 | L10: Queensland | M10: =B10&"-Q"&C10 -> 2012-Q1 | N10: =INDEX(Sheet1!$B$2:$GX$9, MATCH(auscathist!L10, Sheet1!$A$2:$A$9, 0), MATCH(auscathist!M10, Sheet1!$B$1:$GX$1, 0)) -> 4545613
A11: 10 | B11: 2011 | C11: 4 | D11: 40902 | E11: 40902 | F11: Christmas Day Storms | G11: Storm | H11: Melbourne | I11: 728.64 | J11: NA | K11: 781.207 | L11: Victoria | M11: =B11&"-Q"&C11 -> 2011-Q4 | N11: =INDEX(Sheet1!$B$2:$GX$9, MATCH(auscathist!L11, Sheet1!$A$2:$A$9, 0), MATCH(auscathist!M11, Sheet1!$B$1:$GX$1, 0)) -> 5591818
A12: 11 | B12: 2011 | C12: 4 | D12: 40869 | E12: 40871 | F12: Margaret River Bushfires | G12: Bushfire | H12: Margaret River | I12: 53.45 | J12: NA | K12: 57.306 | L12: Western Australia | M12: =B12&"-Q"&C12 -> 2011-Q4 | N12: =INDEX(Sheet1!$B$2:$GX$9, MATCH(auscathist!L12, Sheet1!$A$2:$A$9, 0), MATCH(auscathist!M12, Sheet1!$B$1:$GX$1, 0)) -> 2385947
A13: 12 | B13: 2011 | C13: 1 | D13: 40579 | E13: 40581 | F13: Perth Bushfires | G13: Bushfire | H13: Perth and surrounds | I13: 35.128 | J13: NA | K13: 38.237 | L13: Western Australia | M13: =B13&"-Q"&C13 -> 2011-Q1 | N13: =INDEX(Sheet1!$B$2:$GX$9, MATCH(auscathist!L13, Sheet1!$A$2:$A$9, 0), MATCH(auscathist!M13, Sheet1!$B$1:$GX$1, 0)) -> 2337611
... A17: 16 | B17: 2010 | C17: 4 | D17: 40533 | E17: 40557 | F17: Flooding | G17: Flood | H17: QLD, Rural Toowoomba, Lockyer Valley | I17: 2387.624 | J17: NA | K17: 2636.489 | L17: Queensland | M17: =B17&"-Q"&C17 -> 2010-Q4 | N17: =INDEX(Sheet1!$B$2:$GX$9, MATCH(auscathist!L17, Sheet1!$A$2:$A$9, 0), MATCH(auscathist!M17, Sheet1!$B$1:$GX$1, 0)) -> 4436882
A18: 17 | B18: 2010 | C18: 1 | D18: 40259 | E18: NA | F18: Perth Storm | G18: Storm | H18: Perth | I18: 1053 | J18: 1019 | K18: 1092.515 | L18: Western Australia | M18: =B18&"-Q"&C18 -> 2010-Q1 | N18: =INDEX(Sheet1!$B$2:$GX$9, MATCH(auscathist!L18, Sheet1!$A$2:$A$9, 0), MATCH(auscathist!M18, Sheet1!$B$1:$GX$1, 0)) -> 2278589
A19: 18 | B19: 2010 | C19: 1 | D19: 40243 | E19: NA | F19: Melbourne Storm | G19: Storm | H19: Melbourne | I19: 1044 | J19: 1160 | K19: 1243.687 | L19: Victoria | M19: =B19&"-Q"&C19 -> 2010-Q1 | N19: =INDEX(Sheet1!$B$2:$GX$9, MATCH(auscathist!L19, Sheet1!$A$2:$A$9, 0), MATCH(auscathist!M19, Sheet1!$B$1:$GX$1, 0)) -> 5445172
A20: 19 | B20: 2010 | C20: 1 | D20: 40242 | E20: NA | F20: West QLD flooding | G20: Flood | H20: QLD | I20: 46.7 | J20: 49 | K20: 52.535 | L20: Queensland | M20: =B20&"-Q"&C20 -> 2010-Q1 | N20: =INDEX(Sheet1!$B$2:$GX$9, MATCH(auscathist!L20, Sheet1!$A$2:$A$9, 0), MATCH(auscathist!M20, Sheet1!$B$1:$GX$1, 0)) -> 4387801
A21: 20 | B21: 2009 | C21: 4 | D21: 40178 | E21: NA | F21: Toodyay Bushfires | G21: Bushfire | H21: Toodyay WA | I21: 7.4 | J21: 8 | K21: 8.577 | L21: Western Australia | M21: =B21&"-Q"&C21 -> 2009-Q4 | N21: =INDEX(Sheet1!$B$2:$GX$9, MATCH(auscathist!L21, Sheet1!$A$2:$A$9, 0), MATCH(auscathist!M21, Sheet1!$B$1:$GX$1, 0)) -> 2263747
A22: 21 | B22: 2009 | C22: 2 | D22: 39954 | E22: NA | F22: Inundation , Storm Damage | G22: Storm | H22: South East Queensland , Northern NSW | I22: 48 | J22: 55 | K22: 58.968 | L22: Queensland | M22: =B22&"-Q"&C22 -> 2009-Q2 | N22: =INDEX(Sheet1!$B$2:$GX$9, MATCH(auscathist!L22, Sheet1!$A$2:$A$9, 0), MATCH(auscathist!M22, Sheet1!$B$1:$GX$1, 0)) -> 4328771
A23: 22 | B23: 2009 | C23: 2 | D23: 39913 | E23: NA | F23: Flooding | G23: Flood | H23: Northern NSW | I23: 37 | J23: 40 | K23: 42.886 | L23: New South Wales | M23: =B23&"-Q"&C23 -> 2009-Q2 | N23: =INDEX(Sheet1!$B$2:$GX$9, MATCH(auscathist!L23, Sheet1!$A$2:$A$9, 0), MATCH(auscathist!M23, Sheet1!$B$1:$GX$1, 0)) -> 7053755
A24: 23 | B24: 2009 | C24: 1 | D24: 39851 | E24: NA | F24: Victorian fires | G24: Other | H24: VIC | I24: 1070 | J24: 1266 | K24: 1357.335 | L24: Victoria | M24: =B24&"-Q"&C24 -> 2009-Q1 | N24: =INDEX(Sheet1!$B$2:$GX$9, MATCH(auscathist!L24, Sheet1!$A$2:$A$9, 0), MATCH(auscathist!M24, Sheet1!$B$1:$GX$1, 0)) -> 5347672
A25: 24 | B25: 2009 | C25: 1 | D25: 39826 | E25: NA | F25: Floods | G25: Flood | H25: Far North Queensland | I25: 19 | J25: 22 | K25: 23.587 | L25: Queensland | M25: =B25&"-Q"&C25 -> 2009-Q1 | N25: =INDEX(Sheet1!$B$2:$GX$9, MATCH(auscathist!L25, Sheet1!$A$2:$A$9, 0), MATCH(auscathist!M25, Sheet1!$B$1:$GX$1, 0)) -> 4305605
A26: 25 | B26: 2008 | C26: 4 | D26: 39768 | E26: NA | F26: Brisbane storms | G26: Storm | H26: Brisbane | I26: 309 | J26: 355 | K26: 380.611 | L26: Queensland | M26: =B26&"-Q"&C26 -> 2008-Q4 | N26: =INDEX(Sheet1!$B$2:$GX$9, MATCH(auscathist!L26, Sheet1!$A$2:$A$9, 0), MATCH(auscathist!M26, Sheet1!$B$1:$GX$1, 0)) -> 4275551
A27: 26 | B27: 2008 | C27: 2 | D27: 39602 | E27: NA | F27: Gas Supply Disruption Varanus Isl, | G27: Other | H27: Western Australia | I27: 230 | J27: 279 | K27: 299.128 | L27: Western Australia | M27: =B27&"-Q"&C27 -> 2008-Q2 | N27: =INDEX(Sheet1!$B$2:$GX$9, MATCH(auscathist!L27, Sheet1!$A$2:$A$9, 0), MATCH(auscathist!M27, Sheet1!$B$1:$GX$1, 0)) -> 2171700
A28: 27 | B28: 2008 | C28: 2 | D28: 39558 | E28: NA | F28: Wind Storm | G28: Storm | H28: SA, TAS , VIC | I28: 65 | J28: 79 | K28: 84.699 | L28: Victoria | M28: =B28&"-Q"&C28 -> 2008-Q2 | N28: =INDEX(Sheet1!$B$2:$GX$9, MATCH(auscathist!L28, Sheet1!$A$2:$A$9, 0), MATCH(auscathist!M28, Sheet1!$B$1:$GX$1, 0)) -> 5256375
A29: 28 | B29: 2008 | C29: 1 | D29: 39492 | E29: NA | F29: Flood Storm | G29: Flood, Storm | H29: Mackay | I29: 410 | J29: 507 | K29: 543.577 | L29: Queensland | M29: =B29&"-Q"&C29 -> 2008-Q1 | N29: =INDEX(Sheet1!$B$2:$GX$9, MATCH(auscathist!L29, Sheet1!$A$2:$A$9, 0), MATCH(auscathist!M29, Sheet1!$B$1:$GX$1, 0)) -> 4191479
... A33: 32 | B33: 2007 | C33: 4 | D33: 39381 | E33: NA | F33: Severe Storms | G33: Storm | H33: Lismore Region | I33: 4 | J33: 5 | K33: 5.361 | L33: New South Wales | M33: =B33&"-Q"&C33 -> 2007-Q4 | N33: =INDEX(Sheet1!$B$2:$GX$9, MATCH(auscathist!L33, Sheet1!$A$2:$A$9, 0), MATCH(auscathist!M33, Sheet1!$B$1:$GX$1, 0)) -> 6883852
A34: 33 | B34: 2007 | C34: 2 | D34: 39241 | E34: 39243 | F34: Severe Storm | G34: Storm | H34: Newcastle , Hunter Valley | I34: 1480 | J34: 1742 | K34: 1867.675 | L34: New South Wales | M34: =B34&"-Q"&C34 -> 2007-Q2 | N34: =INDEX(Sheet1!$B$2:$GX$9, MATCH(auscathist!L34, Sheet1!$A$2:$A$9, 0), MATCH(auscathist!M34, Sheet1!$B$1:$GX$1, 0)) -> 6834156
A35: 34 | B35: 2007 | C35: 4 | D35: 39364 | E35: NA | F35: Hail Storm | G35: Hailstorm | H35: Lismore Region | I35: 97 | J35: 109 | K35: 116.864 | L35: New South Wales | M35: =B35&"-Q"&C35 -> 2007-Q4 | N35: =INDEX(Sheet1!$B$2:$GX$9, MATCH(auscathist!L35, Sheet1!$A$2:$A$9, 0), MATCH(auscathist!M35, Sheet1!$B$1:$GX$1, 0)) -> 6883852
A36: 35 | B36: 2007 | C36: 2 | D36: 39249 | E36: NA | F36: Severe Storm | G36: Storm | H36: Gippsland VIC | I36: 15 | J36: 18 | K36: 19.299 | L36: Victoria | M36: =B36&"-Q"&C36 -> 2007-Q2 | N36: =INDEX(Sheet1!$B$2:$GX$9, MATCH(auscathist!L36, Sheet1!$A$2:$A$9, 0), MATCH(auscathist!M36, Sheet1!$B$1:$GX$1, 0)) -> 5153522
A37: 36 | B37: 2007 | C37: 1 | D37: 39149 | E37: NA | F37: Cyclone George , Jacob | G37: Cyclone | H37: George , Jacob - Pilbara WA | I37: 8 | J37: 12 | K37: 12.866 | L37: Western Australia | M37: =B37&"-Q"&C37 -> 2007-Q1 | N37: =INDEX(Sheet1!$B$2:$GX$9, MATCH(auscathist!L37, Sheet1!$A$2:$A$9, 0), MATCH(auscathist!M37, Sheet1!$B$1:$GX$1, 0)) -> 2093633
A38: 37 | B38: 2007 | C38: 1 | D38: 39098 | E38: NA | F38: Severe Storm | G38: Storm | H38: Wagga Wagga NSW | I38: 4 | J38: 5 | K38: 5.361 | L38: New South Wales | M38: =B38&"-Q"&C38 -> 2007-Q1 | N38: =INDEX(Sheet1!$B$2:$GX$9, MATCH(auscathist!L38, Sheet1!$A$2:$A$9, 0), MATCH(auscathist!M38, Sheet1!$B$1:$GX$1, 0)) -> 6815359
A39: 38 | B39: 2007 | C39: 1 | D39: 39097 | E39: NA | F39: Severe Storm | G39: Storm | H39: Nyngan NSW | I39: 2 | J39: 2 | K39: 2.144 | L39: New South Wales | M39: =B39&"-Q"&C39 -> 2007-Q1 | N39: =INDEX(Sheet1!$B$2:$GX$9, MATCH(auscathist!L39, Sheet1!$A$2:$A$9, 0), MATCH(auscathist!M39, Sheet1!$B$1:$GX$1, 0)) -> 6815359
A40: 39 | B40: 2006 | C40: 4 | D40: 39021 | E40: NA | F40: Hail | G40: Hailstorm | H40: Newcastle , Lower Hunter Valley | I40: 51 | J40: 60 | K40: 64.329 | L40: New South Wales | M40: =B40&"-Q"&C40 -> 2006-Q4 | N40: =INDEX(Sheet1!$B$2:$GX$9, MATCH(auscathist!L40, Sheet1!$A$2:$A$9, 0), MATCH(auscathist!M40, Sheet1!$B$1:$GX$1, 0)) -> 6786160
A41: 40 | B41: 2006 | C41: 3 | D41: 38936 | E41: NA | F41: Storm | G41: Storm | H41: South West WA | I41: 5.2 | J41: 9 | K41: 9.649 | L41: Western Australia | M41: =B41&"-Q"&C41 -> 2006-Q3 | N41: =INDEX(Sheet1!$B$2:$GX$9, MATCH(auscathist!L41, Sheet1!$A$2:$A$9, 0), MATCH(auscathist!M41, Sheet1!$B$1:$GX$1, 0)) -> 2064032
A42: 41 | B42: 2006 | C42: 1 | D42: 38796 | E42: NA | F42: Cyclone Larry | G42: Cyclone | H42: Larry - North QLD | I42: 540 | J42: 609 | K42: 652.936 | L42: Queensland | M42: =B42&"-Q"&C42 -> 2006-Q1 | N42: =INDEX(Sheet1!$B$2:$GX$9, MATCH(auscathist!L42, Sheet1!$A$2:$A$9, 0), MATCH(auscathist!M42, Sheet1!$B$1:$GX$1, 0)) -> 3987653
A43: 42 | B43: 2006 | C43: 1 | D43: 38749 | E43: NA | F43: Bushfire | G43: Bushfire | H43: Widespread | I43: 14 | J43: 16 | K43: 17.154 | L43: Victoria | M43: =B43&"-Q"&C43 -> 2006-Q1 | N43: =INDEX(Sheet1!$B$2:$GX$9, MATCH(auscathist!L43, Sheet1!$A$2:$A$9, 0), MATCH(auscathist!M43, Sheet1!$B$1:$GX$1, 0)) -> 5048207
A44: 43 | B44: 2006 | C44: 1 | D44: 38737 | E44: NA | F44: Bushfire | G44: Bushfire | H44: North, West , East VIC | I44: 22.4 | J44: 28 | K44: 30.02 | L44: Victoria | M44: =B44&"-Q"&C44 -> 2006-Q1 | N44: =INDEX(Sheet1!$B$2:$GX$9, MATCH(auscathist!L44, Sheet1!$A$2:$A$9, 0), MATCH(auscathist!M44, Sheet1!$B$1:$GX$1, 0)) -> 5048207
A45: 44 | B45: 2005 | C45: 4 | D45: 38701 | E45: NA | F45: Storm | G45: Storm | H45: Hunter Valley | I45: 10 | J45: 36 | K45: 38.597 | L45: New South Wales | M45: =B45&"-Q"&C45 -> 2005-Q4 | N45: =INDEX(Sheet1!$B$2:$GX$9, MATCH(auscathist!L45, Sheet1!$A$2:$A$9, 0), MATCH(auscathist!M45, Sheet1!$B$1:$GX$1, 0)) -> 6718023
A46: 45 | B46: 2005 | C46: 4 | D46: 38663 | E46: NA | F46: Flood, Storm | G46: Flood, Storm | H46: Central West NSW | I46: 3 | J46: 4 | K46: 4.289 | L46: New South Wales | M46: =B46&"-Q"&C46 -> 2005-Q4 | N46: =INDEX(Sheet1!$B$2:$GX$9, MATCH(auscathist!L46, Sheet1!$A$2:$A$9, 0), MATCH(auscathist!M46, Sheet1!$B$1:$GX$1, 0)) -> 6718023
...

Sheet Sheet1
B1: =B12&"-"&B11 -> 1964-Q1 | C1: =C12&"-"&C11 -> 1964-Q2 | D1: =D12&"-"&D11 -> 1964-Q3 | E1: =E12&"-"&E11 -> 1964-Q4 | F1: =F12&"-"&F11 -> 1965-Q1 | G1: =G12&"-"&G11 -> 1965-Q2 | H1: =H12&"-"&H11 -> 1965-Q3 | I1: =I12&"-"&I11 -> 1965-Q4 | ... BQ1: =BQ12&"-"&BQ11 -> 1980-Q4 | BR1: 1981-Q1 | BS1: 1981-Q2 | BT1: 1981-Q3 | BU1: 1981-Q4 | BV1: 1982-Q1 | BW1: 1982-Q2 | BX1: 1982-Q3 | BY1: 1982-Q4 | BZ1: 1983-Q1 | CA1: 1983-Q2 | CB1: 1983-Q3 | CC1: 1983-Q4 | CD1: 1984-Q1 | CE1: 1984-Q2 | CF1: 1984-Q3 | CG1: 1984-Q4 | CH1: 1985-Q1 | CI1: 1985-Q2 | CJ1: 1985-Q3 | CK1: 1985-Q4 | CL1: 1986-Q1 | CM1: 1986-Q2 | CN1: 1986-Q3 | CO1: 1986-Q4 | CP1: 1987-Q1 | CQ1: 1987-Q2 | CR1: 1987-Q3 | CS1: 1987-Q4 | CT1: 1988-Q1 | CU1: 1988-Q2 | CV1: 1988-Q3 | CW1: 1988-Q4 | CX1: 1989-Q1 | CY1: 1989-Q2 | CZ1: 1989-Q3 | DA1: 1989-Q4 | DB1: 1990-Q1 | DC1: 1990-Q2 | DD1: 1990-Q3 | DE1: 1990-Q4 | DF1: 1991-Q1 | DG1: 1991-Q2 | DH1: 1991-Q3 | DI1: 1991-Q4 | DJ1: 1992-Q1 | DK1: 1992-Q2 | DL1: 1992-Q3 | DM1: 1992-Q4 | DN1: 1993-Q1 | DO1: 1993-Q2 | DP1: 1993-Q3 | DQ1: 1993-Q4 | DR1: 1994-Q1 | DS1: 1994-Q2 | DT1: 1994-Q3 | DU1: 1994-Q4 | DV1: 1995-Q1 | DW1: 1995-Q2 | DX1: 1995-Q3 | DY1: 1995-Q4 | DZ1: 1996-Q1 | EA1: 1996-Q2 | EB1: 1996-Q3 | EC1: 1996-Q4 | ED1: 1997-Q1 | EE1: 1997-Q2 | EF1: 1997-Q3 | EG1: 1997-Q4 | EH1: 1998-Q1 | EI1: 1998-Q2 | EJ1: 1998-Q3 | EK1: 1998-Q4 | EL1: 1999-Q1 | EM1: 1999-Q2 | EN1: 1999-Q3 | EO1: 1999-Q4 | EP1: 2000-Q1 | EQ1: 2000-Q2 | ER1: 2000-Q3 | ES1: 2000-Q4 | ET1: 2001-Q1 | EU1: 2001-Q2 | EV1: 2001-Q3 | EW1: 2001-Q4 | EX1: 2002-Q1 | EY1: 2002-Q2 | EZ1: 2002-Q3 | FA1: 2002-Q4 | FB1: 2003-Q1 | FC1: 2003-Q2 | FD1: 2003-Q3 | FE1: 2003-Q4 | FF1: 2004-Q1 | FG1: 2004-Q2 | FH1: 2004-Q3 | FI1: 2004-Q4 | FJ1: 2005-Q1 | FK1: 2005-Q2 | FL1: 2005-Q3 | FM1: 2005-Q4 | FN1: 2006-Q1 | FO1: 2006-Q2 | FP1: 2006-Q3 | FQ1: 2006-Q4 | FR1: 2007-Q1 | FS1: 2007-Q2 | FT1: 2007-Q3 | FU1: 2007-Q4 | FV1: 2008-Q1 | FW1: 2008-Q2 | FX1: 2008-Q3 | FY1: 2008-Q4 | FZ1: 2009-Q1 | GA1: 2009-Q2 | GB1: 2009-Q3 | GC1: 2009-Q4 | GD1: 2010-Q1 | GE1: 2010-Q2 | GF1: 2010-Q3 | GG1: 2010-Q4 | GH1: 2011-Q1 | GI1: 2011-Q2 | GJ1: 2011-Q3 | GK1: 2011-Q4 | GL1: 2012-Q1 | GM1: 2012-Q2 | GN1: 2012-Q3 | GO1: 2012-Q4 | GP1: 2013-Q1 | GQ1: 2013-Q2 | GR1: 2013-Q3 | GS1: 2013-Q4 | GT1: 2014-Q1 | GU1: 2014-Q2 | GV1: 2014-Q3 | GW1: 2014-Q4 | GX1: 2015-Q1
A2: New South Wales | B2: =C2/(1+((D2/C2)-1)) -> 4161874.3 | C2: =D2/(1+((E2/D2)-1)) -> 4175700.3 | D2: =E2/(1+((F2/E2)-1)) -> 4189572.2 | E2: =F2/(1+((G2/F2)-1)) -> 4203490.2 | F2: =G2/(1+((H2/G2)-1)) -> 4217454.5 | G2: =H2/(1+((I2/H2)-1)) -> 4231465.1 | H2: =I2/(1+((J2/I2)-1)) -> 4245522.3 | I2: =J2/(1+((K2/J2)-1)) -> 4259626.2 | ... BS2: =BT2/(1+((BU2/BT2)-1)) -> 5232073.7 | BT2: 5249455 | BU2: 5266894 | BV2: 5286119 | BW2: 5303580 | BX2: 5315846 | BY2: 5328221 | BZ2: 5344027 | CA2: 5352959 | CB2: 5363744 | CC2: 5374915 | CD2: 5389180 | CE2: 5402729 | CF2: 5416536 | CG2: 5431752 | CH2: 5451549 | CI2: 5464512 | CJ2: 5478254 | CK2: 5496467 | CL2: 5516377 | CM2: 5531526 | CN2: 5549928 | CO2: 5574251 | CP2: 5596207 | CQ2: 5616736 | CR2: 5639899 | CS2: 5666219 | CT2: 5689397 | CU2: 5707309 | CV2: 5730331 | CW2: 5752254 | CX2: 5769720 | CY2: 5776283 | CZ2: 5785625 | DA2: 5803079 | DB2: 5818151 | DC2: 5834021 | DD2: 5849534 | DE2: 5862497 | DF2: 5883248 | DG2: 5898731 | DH2: 5916714 | DI2: 5928072 | DJ2: 5946386 | DK2: 5957822 | DL2: 5970754 | DM2: 5977823 | DN2: 5990424 | DO2: 5995055 | DP2: 6009659 | DQ2: 6020171 | DR2: 6037096 | DS2: 6044819 | DT2: 6063058 | DU2: 6071872 | DV2: 6087910 | DW2: 6105560 | DX2: 6124648 | DY2: 6143971 | DZ2: 6159806 | EA2: 6176461 | EB2: 6196251 | EC2: 6214548 | ED2: 6234303 | EE2: 6246267 | EF2: 6260867 | EG2: 6274966 | EH2: 6295260 | EI2: 6305799 | EJ2: 6324111 | EK2: 6338790 | EL2: 6360552 | EM2: 6375103 | EN2: 6393100 | EO2: 6409971 | EP2: 6431826 | EQ2: 6446558 | ER2: 6465614 | ES2: 6485081 | ET2: 6513844 | EU2: 6530349 | EV2: 6544891 | EW2: 6558484 | EX2: 6575296 | EY2: 6580807 | EZ2: 6590659 | FA2: 6599441 | FB2: 6615712 | FC2: 6620715 | FD2: 6627538 | FE2: 6634509 | FF2: 6648280 | FG2: 6650735 | FH2: 6660416 | FI2: 6669206 | FJ2: 6685875 | FK2: 6693206 | FL2: 6707429 | FM2: 6718023 | FN2: 6735528 | FO2: 6742690 | FP2: 6766133 | FQ2: 6786160 | FR2: 6815359 | FS2: 6834156 | FT2: 6859736 | FU2: 6883852 | FV2: 6919907 | FW2: 6943461 | FX2: 6972395 | FY2: 7001782 | FZ2: 7032423 | GA2: 7053755 | GB2: 7079175 | GC2: 7101504 | GD2: 7128356 | GE2: 7144292 | GF2: 7162726 | GG2: 7179891 | GH2: 7204737 | GI2: 7218529 | GJ2: 7239528 | GK2: 7258722 | GL2: 7284982 | GM2: 7304244 | GN2: 7327614 | GO2: 7353189 | GP2: 7382957 | GQ2: 7404032 | GR2: 7430904 | GS2: 7454938 | GT2: 7487834 | GU2: 7508353 | GV2: 7536277 | GW2: 7562171 | GX2: 7595731
A3: Victoria | B3: =C3/(1+((D3/C3)-1)) -> 3254758.8 | C3: =D3/(1+((E3/D3)-1)) -> 3263859.4 | D3: =E3/(1+((F3/E3)-1)) -> 3272985.4 | E3: =F3/(1+((G3/F3)-1)) -> 3282136.9 | F3: =G3/(1+((H3/G3)-1)) -> 3291314 | G3: =H3/(1+((I3/H3)-1)) -> 3300516.8 | H3: =I3/(1+((J3/I3)-1)) -> 3309745.3 | I3: =J3/(1+((K3/J3)-1)) -> 3318999.5 | ... BS3: =BT3/(1+((BU3/BT3)-1)) -> 3946298.9 | BT3: 3957333 | BU3: 3968398 | BV3: 3980826 | BW3: 3992870 | BX3: 4002731 | BY3: 4012687 | BZ3: 4025254 | CA3: 4035702 | CB3: 4045185 | CC3: 4054498 | CD3: 4066209 | CE3: 4076492 | CF3: 4086549 | CG3: 4097640 | CH3: 4109741 | CI3: 4120068 | CJ3: 4129796 | CK3: 4140421 | CL3: 4151053 | CM3: 4160856 | CN3: 4171942 | CO3: 4183842 | CP3: 4197414 | CQ3: 4210111 | CR3: 4223707 | CS3: 4234945 | CT3: 4249985 | CU3: 4262569 | CV3: 4280376 | CW3: 4295300 | CX3: 4309978 | CY3: 4320164 | CZ3: 4333537 | DA3: 4348225 | DB3: 4364548 | DC3: 4378592 | DD3: 4391183 | DE3: 4400707 | DF3: 4413410 | DG3: 4420373 | DH3: 4429409 | DI3: 4435083 | DJ3: 4445141 | DK3: 4450217 | DL3: 4454836 | DM3: 4458219 | DN3: 4463265 | DO3: 4462766 | DP3: 4464794 | DQ3: 4466738 | DR3: 4471010 | DS3: 4472989 | DT3: 4479378 | DU3: 4483205 | DV3: 4491289 | DW3: 4497660 | DX3: 4506386 | DY3: 4517353 | DZ3: 4527573 | EA3: 4534984 | EB3: 4544480 | EC3: 4552904 | ED3: 4565356 | EE3: 4569297 | EF3: 4578175 | EG3: 4586156 | EH3: 4600872 | EI3: 4606970 | EJ3: 4617308 | EK3: 4629345 | EL3: 4645152 | EM3: 4652462 | EN3: 4665626 | EO3: 4677581 | EP3: 4695560 | EQ3: 4704065 | ER3: 4718436 | ES3: 4730855 | ET3: 4753725 | EU3: 4763615 | EV3: 4776052 | EW3: 4790212 | EX3: 4808940 | EY3: 4817774 | EZ3: 4830383 | FA3: 4845024 | FB3: 4864214 | FC3: 4873809 | FD3: 4887826 | FE3: 4900176 | FF3: 4918070 | FG3: 4927149 | FH3: 4943359 | FI3: 4957147 | FJ3: 4978342 | FK3: 4989246 | FL3: 5006241 | FM3: 5023203 | FN3: 5048207 | FO3: 5061266 | FP3: 5083593 | FQ3: 5103965 | FR3: 5134074 | FS3: 5153522 | FT3: 5178515 | FU3: 5199503 | FV3: 5233000 | FW3: 5256375 | FX3: 5286549 | FY3: 5313285 | FZ3: 5347672 | GA3: 5371934 | GB3: 5398874 | GC3: 5419249 | GD3: 5445172 | GE3: 5461101 | GF3: 5478710 | GG3: 5495711 | GH3: 5520378 | GI3: 5537817 | GJ3: 5564662 | GK3: 5591818 | GL3: 5625354 | GM3: 5651091 | GN3: 5680420 | GO3: 5709586 | GP3: 5744915 | GQ3: 5772669 | GR3: 5804499 | GS3: 5832585 | GT3: 5869511 | GU3: 5894917 | GV3: 5927199 | GW3: 5957512 | GX3: 5995205
A4: Queensland | B4: =C4/(1+((D4/C4)-1)) -> 1296022.8 | C4: =D4/(1+((E4/D4)-1)) -> 1307226.5 | D4: =E4/(1+((F4/E4)-1)) -> 1318527 | E4: =F4/(1+((G4/F4)-1)) -> 1329925.2 | F4: =G4/(1+((H4/G4)-1)) -> 1341421.9 | G4: =H4/(1+((I4/H4)-1)) -> 1353018 | H4: =I4/(1+((J4/I4)-1)) -> 1364714.4 | I4: =J4/(1+((K4/J4)-1)) -> 1376511.9 | ... BS4: =BT4/(1+((BU4/BT4)-1)) -> 2347186.4 | BT4: 2367477 | BU4: 2387943 | BV4: 2406355 | BW4: 2424586 | BX4: 2442912 | BY4: 2456475 | BZ4: 2469709 | CA4: 2482282 | CB4: 2493373 | CC4: 2503285 | CD4: 2513443 | CE4: 2523859 | CF4: 2535976 | CG4: 2547078 | CH4: 2559452 | CI4: 2571218 | CJ4: 2583368 | CK4: 2597100 | CL4: 2610205 | CM4: 2624595 | CN4: 2636477 | CO4: 2648778 | CP4: 2662654 | CQ4: 2675107 | CR4: 2688129 | CS4: 2703516 | CT4: 2723992 | CU4: 2739907 | CV4: 2760389 | CW4: 2780869 | CX4: 2806845 | CY4: 2827637 | CZ4: 2847045 | DA4: 2864007 | DB4: 2884170 | DC4: 2899283 | DD4: 2913538 | DE4: 2928713 | DF4: 2947512 | DG4: 2960951 | DH4: 2975984 | DI4: 2990441 | DJ4: 3010322 | DK4: 3023198 | DL4: 3041149 | DM4: 3057138 | DN4: 3081331 | DO4: 3096185 | DP4: 3115843 | DQ4: 3130986 | DR4: 3151365 | DS4: 3166566 | DT4: 3184148 | DU4: 3198877 | DV4: 3218314 | DW4: 3237380 | DX4: 3255117 | DY4: 3271743 | DZ4: 3289507 | EA4: 3303192 | EB4: 3318599 | EC4: 3330579 | ED4: 3343777 | EE4: 3355417 | EF4: 3369184 | EG4: 3380394 | EH4: 3393483 | EI4: 3404484 | EJ4: 3416076 | EK4: 3427505 | EL4: 3442196 | EM4: 3453936 | EN4: 3466399 | EO4: 3481034 | EP4: 3497147 | EQ4: 3509458 | ER4: 3523446 | ES4: 3537670 | ET4: 3556466 | EU4: 3571469 | EV4: 3590969 | EW4: 3611203 | EX4: 3631451 | EY4: 3653123 | EZ4: 3676870 | FA4: 3700791 | FB4: 3723239 | FC4: 3743121 | FD4: 3765109 | FE4: 3788560 | FF4: 3810921 | FG4: 3829970 | FH4: 3849852 | FI4: 3872351 | FJ4: 3896951 | FK4: 3918494 | FL4: 3940494 | FM4: 3964175 | FN4: 3987653 | FO4: 4007992 | FP4: 4031580 | FQ4: 4055845 | FR4: 4084531 | FS4: 4111018 | FT4: 4134958 | FU4: 4159990 | FV4: 4191479 | FW4: 4219505 | FX4: 4247991 | FY4: 4275551 | FZ4: 4305605 | GA4: 4328771 | GB4: 4350135 | GC4: 4367454 | GD4: 4387801 | GE4: 4404744 | GF4: 4421470 | GG4: 4436882 | GH4: 4457971 | GI4: 4476778 | GJ4: 4498104 | GK4: 4518649 | GL4: 4545613 | GM4: 4568687 | GN4: 4592100 | GO4: 4611304 | GP4: 4634430 | GQ4: 4652824 | GR4: 4670784 | GS4: 4685439 | GT4: 4705187 | GU4: 4719653 | GV4: 4734613 | GW4: 4747263 | GX4: 4764439
A5: South Australia | B5: =C5/(1+((D5/C5)-1)) -> 1072594.6 | C5: =D5/(1+((E5/D5)-1)) -> 1075794 | D5: =E5/(1+((F5/E5)-1)) -> 1079002.9 | E5: =F5/(1+((G5/F5)-1)) -> 1082221.4 | F5: =G5/(1+((H5/G5)-1)) -> 1085449.4 | G5: =H5/(1+((I5/H5)-1)) -> 1088687.1 | H5: =I5/(1+((J5/I5)-1)) -> 1091934.5 | I5: =J5/(1+((K5/J5)-1)) -> 1095191.5 | ... BS5: =BT5/(1+((BU5/BT5)-1)) -> 1317305.7 | BT5: 1321235 | BU5: 1325176 | BV5: 1328670 | BW5: 1331108 | BX5: 1334090 | BY5: 1337783 | BZ5: 1342193 | CA5: 1345775 | CB5: 1349553 | CC5: 1353208 | CD5: 1356511 | CE5: 1360048 | CF5: 1362611 | CG5: 1365333 | CH5: 1368721 | CI5: 1371197 | CJ5: 1373324 | CK5: 1376838 | CL5: 1380317 | CM5: 1382550 | CN5: 1384840 | CO5: 1387499 | CP5: 1390436 | CQ5: 1392764 | CR5: 1395947 | CS5: 1398959 | CT5: 1402329 | CU5: 1404909 | CV5: 1408705 | CW5: 1412323 | CX5: 1416938 | CY5: 1419029 | CZ5: 1421671 | DA5: 1425461 | DB5: 1429541 | DC5: 1432056 | DD5: 1435497 | DE5: 1438882 | DF5: 1443371 | DG5: 1446299 | DH5: 1449037 | DI5: 1450862 | DJ5: 1454160 | DK5: 1455442 | DL5: 1456178 | DM5: 1457241 | DN5: 1457895 | DO5: 1458632 | DP5: 1460306 | DQ5: 1461102 | DR5: 1462557 | DS5: 1463089 | DT5: 1463714 | DU5: 1463977 | DV5: 1464763 | DW5: 1465340 | DX5: 1465759 | DY5: 1466605 | DZ5: 1467943 | EA5: 1469079 | EB5: 1470334 | EC5: 1471997 | ED5: 1474442 | EE5: 1475658 | EF5: 1477371 | EG5: 1479003 | EH5: 1482137 | EI5: 1483270 | EJ5: 1484580 | EK5: 1487042 | EL5: 1489729 | EM5: 1490934 | EN5: 1493030 | EO5: 1495218 | EP5: 1496828 | EQ5: 1497503 | ER5: 1498934 | ES5: 1500129 | ET5: 1502299 | EU5: 1503461 | EV5: 1504992 | EW5: 1507825 | EX5: 1510013 | EY5: 1511567 | EZ5: 1513662 | FA5: 1515723 | FB5: 1518570 | FC5: 1520399 | FD5: 1522193 | FE5: 1524727 | FF5: 1526994 | FG5: 1528189 | FH5: 1530521 | FI5: 1532562 | FJ5: 1536798 | FK5: 1538804 | FL5: 1542004 | FM5: 1544852 | FN5: 1550135 | FO5: 1552529 | FP5: 1557332 | FQ5: 1561300 | FR5: 1567206 | FS5: 1570619 | FT5: 1574537 | FU5: 1578489 | FV5: 1584408 | FW5: 1588665 | FX5: 1593725 | FY5: 1597880 | FZ5: 1604142 | GA5: 1608902 | GB5: 1614593 | GC5: 1618578 | GD5: 1624033 | GE5: 1627322 | GF5: 1630230 | GG5: 1632482 | GH5: 1636759 | GI5: 1639614 | GJ5: 1643402 | GK5: 1647183 | GL5: 1652716 | GM5: 1656725 | GN5: 1660198 | GO5: 1663082 | GP5: 1668056 | GQ5: 1671488 | GR5: 1675313 | GS5: 1678052 | GT5: 1683544 | GU5: 1686945 | GV5: 1690133 | GW5: 1693107 | GX5: 1698433
A6: Western Australia | B6: =C6/(1+((D6/C6)-1)) -> 815089.97 | C6: =D6/(1+((E6/D6)-1)) -> 820645.18 | D6: =E6/(1+((F6/E6)-1)) -> 826238.25 | E6: =F6/(1+((G6/F6)-1)) -> 831869.44 | F6: =G6/(1+((H6/G6)-1)) -> 837539.02 | G6: =H6/(1+((I6/H6)-1)) -> 843247.23 | H6: =I6/(1+((J6/I6)-1)) -> 848994.34 | I6: =J6/(1+((K6/J6)-1)) -> 854780.63 | ... BS6: =BT6/(1+((BU6/BT6)-1)) -> 1302407.5 | BT6: 1311284 | BU6: 1320221 | BV6: 1329700 | BW6: 1338899 | BX6: 1348096 | BY6: 1354971 | BZ6: 1361874 | CA6: 1369050 | CB6: 1375244 | CC6: 1381011 | CD6: 1385878 | CE6: 1391237 | CF6: 1397817 | CG6: 1403032 | CH6: 1410377 | CI6: 1418564 | CJ6: 1427370 | CK6: 1436900 | CL6: 1447254 | CM6: 1459019 | CN6: 1468413 | CO6: 1477398 | CP6: 1486905 | CQ6: 1496248 | CR6: 1505294 | CS6: 1513355 | CT6: 1525576 | CU6: 1535167 | CV6: 1548042 | CW6: 1558914 | CX6: 1569712 | CY6: 1578434 | CZ6: 1588186 | DA6: 1596225 | DB6: 1605959 | DC6: 1613049 | DD6: 1619848 | DE6: 1624390 | DF6: 1631357 | DG6: 1636067 | DH6: 1642746 | DI6: 1647408 | DJ6: 1654244 | DK6: 1658544 | DL6: 1664755 | DM6: 1668515 | DN6: 1674250 | DO6: 1678722 | DP6: 1684972 | DQ6: 1690348 | DR6: 1698534 | DS6: 1704649 | DT6: 1713520 | DU6: 1718549 | DV6: 1727907 | DW6: 1736066 | DX6: 1744788 | DY6: 1751933 | DZ6: 1760445 | EA6: 1768206 | EB6: 1776454 | EC6: 1783556 | ED6: 1793345 | EE6: 1798341 | EF6: 1804800 | EG6: 1810928 | EH6: 1820812 | EI6: 1826440 | EJ6: 1834703 | EK6: 1840078 | EL6: 1848303 | EM6: 1853936 | EN6: 1862033 | EO6: 1866265 | EP6: 1874371 | EQ6: 1879093 | ER6: 1886084 | ES6: 1892531 | ET6: 1901295 | EU6: 1906274 | EV6: 1912214 | EW6: 1917752 | EX6: 1924935 | EY6: 1928512 | EZ6: 1932977 | FA6: 1938610 | FB6: 1946831 | FC6: 1952741 | FD6: 1959430 | FE6: 1966130 | FF6: 1974145 | FG6: 1979542 | FH6: 1986513 | FI6: 1994241 | FJ6: 2004644 | FK6: 2011207 | FL6: 2020359 | FM6: 2029936 | FN6: 2042450 | FO6: 2050581 | FP6: 2064032 | FQ6: 2076867 | FR6: 2093633 | FS6: 2106139 | FT6: 2120776 | FU6: 2135006 | FV6: 2155552 | FW6: 2171700 | FX6: 2191582 | FY6: 2208928 | FZ6: 2228317 | GA6: 2240250 | GB6: 2253355 | GC6: 2263747 | GD6: 2278589 | GE6: 2290845 | GF6: 2305415 | GG6: 2319063 | GH6: 2337611 | GI6: 2353409 | GJ6: 2369612 | GK6: 2385947 | GL6: 2408108 | GM6: 2425507 | GN6: 2442876 | GO6: 2457489 | GP6: 2475242 | GQ6: 2486944 | GR6: 2496285 | GS6: 2502188 | GT6: 2512556 | GU6: 2517608 | GV6: 2524042 | GW6: 2528619 | GX6: 2536604
A7: Tasmania | B7: =C7/(1+((D7/C7)-1)) -> 403594.54 | C7: =D7/(1+((E7/D7)-1)) -> 403932.19 | D7: =E7/(1+((F7/E7)-1)) -> 404270.12 | E7: =F7/(1+((G7/F7)-1)) -> 404608.33 | F7: =G7/(1+((H7/G7)-1)) -> 404946.82 | G7: =H7/(1+((I7/H7)-1)) -> 405285.6 | H7: =I7/(1+((J7/I7)-1)) -> 405624.66 | I7: =J7/(1+((K7/J7)-1)) -> 405964 | ... BS7: =BT7/(1+((BU7/BT7)-1)) -> 427567.3 | BT7: 427925 | BU7: 428283 | BV7: 429445 | BW7: 429845 | BX7: 430308 | BY7: 430974 | BZ7: 431665 | CA7: 432805 | CB7: 433909 | CC7: 435100 | CD7: 436178 | CE7: 437760 | CF7: 438866 | CG7: 440070 | CH7: 441324 | CI7: 442828 | CJ7: 443548 | CK7: 444576 | CL7: 445723 | CM7: 446473 | CN7: 447325 | CO7: 448235 | CP7: 448597 | CQ7: 449226 | CR7: 449373 | CS7: 449820 | CT7: 450572 | CU7: 451148 | CV7: 451905 | CW7: 452781 | CX7: 453932 | CY7: 455258 | CZ7: 456830 | DA7: 458410 | DB7: 460070 | DC7: 462188 | DD7: 463469 | DE7: 464520 | DF7: 465870 | DG7: 466802 | DH7: 467736 | DI7: 468549 | DJ7: 469433 | DK7: 469979 | DL7: 470443 | DM7: 471258 | DN7: 471864 | DO7: 471987 | DP7: 472574 | DQ7: 472983 | DR7: 473143 | DS7: 473499 | DT7: 473972 | DU7: 474076 | DV7: 474411 | DW7: 474515 | DX7: 474941 | DY7: 475148 | DZ7: 475282 | EA7: 475605 | EB7: 475731 | EC7: 475529 | ED7: 475444 | EE7: 474908 | EF7: 474528 | EG7: 474215 | EH7: 473982 | EI7: 473430 | EJ7: 473430 | EK7: 473450 | EL7: 473189 | EM7: 473030 | EN7: 473181 | EO7: 473294 | EP7: 473303 | EQ7: 473123 | ER7: 473035 | ES7: 473200 | ET7: 473662 | EU7: 473668 | EV7: 473530 | EW7: 473890 | EX7: 474218 | EY7: 474152 | EZ7: 474626 | FA7: 475998 | FB7: 477576 | FC7: 478534 | FD7: 479829 | FE7: 481411 | FF7: 482778 | FG7: 483178 | FH7: 483995 | FI7: 484778 | FJ7: 485755 | FK7: 486202 | FL7: 486893 | FM7: 488098 | FN7: 489140 | FO7: 489302 | FP7: 490354 | FQ7: 491515 | FR7: 492625 | FS7: 493262 | FT7: 494547 | FU7: 495858 | FV7: 497552 | FW7: 498568 | FX7: 500062 | FY7: 501774 | FZ7: 503431 | GA7: 504353 | GB7: 505468 | GC7: 506461 | GD7: 508182 | GE7: 508847 | GF7: 509481 | GG7: 510219 | GH7: 511248 | GI7: 511483 | GJ7: 511880 | GK7: 511739 | GL7: 511993 | GM7: 511724 | GN7: 511582 | GO7: 511813 | GP7: 512240 | GQ7: 512231 | GR7: 512510 | GS7: 513015 | GT7: 513681 | GU7: 513621 | GV7: 513898 | GW7: 514040 | GX7: 514812
A8: Northern Territory | B8: =C8/(1+((D8/C8)-1)) -> 30818.502 | C8: =D8/(1+((E8/D8)-1)) -> 31441.834 | D8: =E8/(1+((F8/E8)-1)) -> 32077.774 | E8: =F8/(1+((G8/F8)-1)) -> 32726.576 | F8: =G8/(1+((H8/G8)-1)) -> 33388.5 | G8: =H8/(1+((I8/H8)-1)) -> 34063.813 | H8: =I8/(1+((J8/I8)-1)) -> 34752.784 | I8: =J8/(1+((K8/J8)-1)) -> 35455.691 | ... BS8: =BT8/(1+((BU8/BT8)-1)) -> 122704.2 | BT8: 125186 | BU8: 127718 | BV8: 129593 | BW8: 130314 | BX8: 131517 | BY8: 132784 | BZ8: 134529 | CA8: 135916 | CB8: 137942 | CC8: 139519 | CD8: 140666 | CE8: 142154 | CF8: 143934 | CG8: 145293 | CH8: 146662 | CI8: 148536 | CJ8: 150596 | CK8: 152356 | CL8: 153284 | CM8: 154421 | CN8: 155571 | CO8: 156578 | CP8: 157775 | CQ8: 158205 | CR8: 159142 | CS8: 159040 | CT8: 158959 | CU8: 159026 | CV8: 159804 | CW8: 160536 | CX8: 161050 | CY8: 161179 | CZ8: 161674 | DA8: 162097 | DB8: 162538 | DC8: 163728 | DD8: 164392 | DE8: 165047 | DF8: 165356 | DG8: 165493 | DH8: 166716 | DI8: 167043 | DJ8: 168117 | DK8: 168546 | DL8: 169101 | DM8: 170420 | DN8: 171319 | DO8: 171708 | DP8: 172884 | DQ8: 173590 | DR8: 174237 | DS8: 174908 | DT8: 175543 | DU8: 176761 | DV8: 178692 | DW8: 179602 | DX8: 180698 | DY8: 182829 | DZ8: 183859 | EA8: 184516 | EB8: 186229 | EC8: 187342 | ED8: 188223 | EE8: 189755 | EF8: 190694 | EG8: 191259 | EH8: 192061 | EI8: 192905 | EJ8: 193703 | EK8: 194390 | EL8: 195251 | EM8: 196012 | EN8: 196807 | EO8: 197757 | EP8: 198304 | EQ8: 199149 | ER8: 199816 | ES8: 200045 | ET8: 200789 | EU8: 201743 | EV8: 201995 | EW8: 201751 | EX8: 201880 | EY8: 202251 | EZ8: 202069 | FA8: 201549 | FB8: 201068 | FC8: 201725 | FD8: 201781 | FE8: 201708 | FF8: 202009 | FG8: 202663 | FH8: 203527 | FI8: 203857 | FJ8: 204897 | FK8: 205905 | FL8: 206759 | FM8: 207385 | FN8: 208347 | FO8: 209057 | FP8: 210284 | FQ8: 211029 | FR8: 212372 | FS8: 213748 | FT8: 215180 | FU8: 216618 | FV8: 217912 | FW8: 219874 | FX8: 221464 | FY8: 222526 | FZ8: 223922 | GA8: 226027 | GB8: 227255 | GC8: 227783 | GD8: 228600 | GE8: 229778 | GF8: 230460 | GG8: 230299 | GH8: 230224 | GI8: 231292 | GJ8: 232581 | GK8: 232952 | GL8: 234275 | GM8: 235915 | GN8: 237517 | GO8: 238728 | GP8: 240107 | GQ8: 241722 | GR8: 242301 | GS8: 242304 | GT8: 242790 | GU8: 242894 | GV8: 243201 | GW8: 242753 | GX8: 243059
A9: Australian Capital Territory | B9: =C9/(1+((D9/C9)-1)) -> 184621.69 | C9: =D9/(1+((E9/D9)-1)) -> 185188.19 | D9: =E9/(1+((F9/E9)-1)) -> 185756.42 | E9: =F9/(1+((G9/F9)-1)) -> 186326.4 | F9: =G9/(1+((H9/G9)-1)) -> 186898.13 | G9: =H9/(1+((I9/H9)-1)) -> 187471.61 | H9: =I9/(1+((J9/I9)-1)) -> 188046.86 | I9: =J9/(1+((K9/J9)-1)) -> 188623.86 | ... BS9: =BT9/(1+((BU9/BT9)-1)) -> 228082.15 | BT9: 228782 | BU9: 229484 | BV9: 230990 | BW9: 233045 | BX9: 233778 | BY9: 234996 | BZ9: 236991 | CA9: 238983 | CB9: 240055 | CC9: 241960 | CD9: 243476 | CE9: 245112 | CF9: 246259 | CG9: 247084 | CH9: 248839 | CI9: 251389 | CJ9: 253446 | CK9: 255908 | CL9: 257285 | CM9: 258910 | CN9: 260545 | CO9: 262188 | CP9: 264053 | CQ9: 265477 | CR9: 267375 | CS9: 268787 | CT9: 270957 | CU9: 272129 | CV9: 273087 | CW9: 274105 | CX9: 275867 | CY9: 276432 | CZ9: 277470 | DA9: 279219 | DB9: 280659 | DC9: 282211 | DD9: 283671 | DE9: 285012 | DF9: 287300 | DG9: 289320 | DH9: 290517 | DI9: 291523 | DJ9: 293484 | DK9: 294887 | DL9: 296087 | DM9: 296519 | DN9: 299204 | DO9: 299753 | DP9: 300030 | DQ9: 300490 | DR9: 301413 | DS9: 302194 | DT9: 303134 | DU9: 303289 | DV9: 305388 | DW9: 305838 | DX9: 306880 | DY9: 307022 | DZ9: 308512 | EA9: 309629 | EB9: 310227 | EC9: 310655 | ED9: 310910 | EE9: 310533 | EF9: 310258 | EG9: 310281 | EH9: 311026 | EI9: 311532 | EJ9: 311732 | EK9: 312300 | EL9: 313466 | EM9: 314171 | EN9: 314833 | EO9: 315431 | EP9: 316731 | EQ9: 317235 | ER9: 318079 | ES9: 318941 | ET9: 320526 | EU9: 321538 | EV9: 321942 | EW9: 322874 | EX9: 324187 | EY9: 324627 | EZ9: 325255 | FA9: 325950 | FB9: 327083 | FC9: 327357 | FD9: 327387 | FE9: 327596 | FF9: 328560 | FG9: 328940 | FH9: 329131 | FI9: 329498 | FJ9: 330916 | FK9: 331399 | FL9: 332177 | FM9: 333505 | FN9: 334299 | FO9: 335170 | FP9: 336547 | FQ9: 338381 | FR9: 340544 | FS9: 342644 | FT9: 343341 | FU9: 344176 | FV9: 346477 | FW9: 348368 | FX9: 349543 | FY9: 351101 | FZ9: 353351 | GA9: 354785 | GB9: 356310 | GC9: 357859 | GD9: 360361 | GE9: 361766 | GF9: 362838 | GG9: 364833 | GH9: 366737 | GI9: 367985 | GJ9: 369888 | GK9: 372070 | GL9: 374853 | GM9: 376539 | GN9: 378586 | GO9: 379812 | GP9: 382082 | GQ9: 383257 | GR9: 384690 | GS9: 386318 | GT9: 388190 | GU9: 388799 | GV9: 390654 | GW9: 391981 | GX9: 394491
B11: Q1 | C11: Q2 | D11: Q3 | E11: Q4 | F11: Q1 | G11: Q2 | H11: Q3 | I11: Q4 | J11: Q1 | K11: Q2 | L11: Q3 | M11: Q4 | N11: Q1 | O11: Q2 | P11: Q3 | Q11: Q4 | R11: Q1 | S11: Q2 | T11: Q3 | U11: Q4 | V11: Q1 | W11: Q2 | X11: Q3 | Y11: Q4 | Z11: Q1 | AA11: Q2 | AB11: Q3 | AC11: Q4 | AD11: Q1 | AE11: Q2 | AF11: Q3 | AG11: Q4 | AH11: Q1 | AI11: Q2 | AJ11: Q3 | AK11: Q4 | AL11: Q1 | AM11: Q2 | AN11: Q3 | AO11: Q4 | AP11: Q1 | AQ11: Q2 | AR11: Q3 | AS11: Q4 | AT11: Q1 | AU11: Q2 | AV11: Q3 | AW11: Q4 | AX11: Q1 | AY11: Q2 | AZ11: Q3 | BA11: Q4 | BB11: Q1 | BC11: Q2 | BD11: Q3 | BE11: Q4 | BF11: Q1 | BG11: Q2 | BH11: Q3 | BI11: Q4 | BJ11: Q1 | BK11: Q2 | BL11: Q3 | BM11: Q4 | BN11: Q1 | BO11: Q2 | BP11: Q3 | BQ11: Q4
B12: 1964 | C12: 1964 | D12: 1964 | E12: 1964 | F12: 1965 | G12: 1965 | H12: 1965 | I12: 1965 | J12: 1966 | K12: 1966 | L12: 1966 | M12: 1966 | N12: 1967 | O12: 1967 | P12: 1967 | Q12: 1967 | R12: 1968 | S12: 1968 | T12: 1968 | U12: 1968 | V12: 1969 | W12: 1969 | X12: 1969 | Y12: 1969 | Z12: 1970 | AA12: 1970 | AB12: 1970 | AC12: 1970 | AD12: 1971 | AE12: 1971 | AF12: 1971 | AG12: 1971 | AH12: 1972 | AI12: 1972 | AJ12: 1972 | AK12: 1972 | AL12: 1973 | AM12: 1973 | AN12: 1973 | AO12: 1973 | AP12: 1974 | AQ12: 1974 | AR12: 1974 | AS12: 1974 | AT12: 1975 | AU12: 1975 | AV12: 1975 | AW12: 1975 | AX12: 1976 | AY12: 1976 | AZ12: 1976 | BA12: 1976 | BB12: 1977 | BC12: 1977 | BD12: 1977 | BE12: 1977 | BF12: 1978 | BG12: 1978 | BH12: 1978 | BI12: 1978 | BJ12: 1979 | BK12: 1979 | BL12: 1979 | BM12: 1979 | BN12: 1980 | BO12: 1980 | BP12: 1980 | BQ12: 1980
