Workbook

Sheet nzcathist
B1: Year | C1: Quarter | D1: Date | E1: FirstDay | F1: Event | G1: Type | H1: Location | I1: OriginalCost | J1: NormCost2011 | K1: NormCost2014 | L1: Cities | M1: exposure
A2: 1 | B2: 2014 | C2: 4 | D2: 46300 | E2: 41917 | F2: Auckland Power Outage | G2: Power outage | H2: Auckland | I2: 2 | J2: NA | K2: 2 | L2: Auckland,Pukekohe | M2: {=SUM( IFERROR( _xlfn.XLOOKUP( TRIM(_xlfn.TEXTSPLIT(nzcathist!L2, ",")), Sheet1!$A$2:$A$62, INDEX(Sheet1!$B$2:$AY$62, , MATCH(nzcathist!B2, Sheet1!$B$1:$AY$1, 0)) ), 0 ) )} -> 1418385.1
A3: 2 | B3: 2014 | C3: 2 | D3: 46198 | E3: 41815 | F3: Nelson-Tasman Floods | G3: Flood | H3: Nelson, Tasman | I3: 2.7 | J3: NA | K3: 2.72 | L3: Nelson,Blenheim,Greymouth,Westport,Hokitika,Christchurch,Ashburton,Rangiora,Timaru,Waimate,Temuka | M3: {=SUM( IFERROR( _xlfn.XLOOKUP( TRIM(_xlfn.TEXTSPLIT(nzcathist!L3, ",")), Sheet1!$A$2:$A$62, INDEX(Sheet1!$B$2:$AY$62, , MATCH(nzcathist!B3, Sheet1!$B$1:$AY$1, 0)) ), 0 ) )} -> 553504.91
A4: 3 | B4: 2014 | C4: 2 | D4: 9-11Jun | E4: 41799 | F4: Severe Weather North and South Islands | G4: Weather | H4: North and South Islands | I4: 37.6 | J4: NA | K4: 37.85 | L4: Nationwide | M4: {=SUM( IFERROR( _xlfn.XLOOKUP( TRIM(_xlfn.TEXTSPLIT(nzcathist!L4, ",")), Sheet1!$A$2:$A$62, INDEX(Sheet1!$B$2:$AY$62, , MATCH(nzcathist!B4, Sheet1!$B$1:$AY$1, 0)) ), 0 ) )} -> 4567520
A5: 4 | B5: 2014 | C5: 2 | D5: 46129 | E5: 41746 | F5: Easter Weekend Storm and Floods | G5: Flood, Storm | H5: NA | I5: 55.3 | J5: NA | K5: 55.67 | L5: Nationwide | M5: {=SUM( IFERROR( _xlfn.XLOOKUP( TRIM(_xlfn.TEXTSPLIT(nzcathist!L5, ",")), Sheet1!$A$2:$A$62, INDEX(Sheet1!$B$2:$AY$62, , MATCH(nzcathist!B5, Sheet1!$B$1:$AY$1, 0)) ), 0 ) )} -> 4567520
A6: 5 | B6: 2014 | C6: 1 | D6: 15-16Mar | E6: 41713 | F6: Cyclone Lusi | G6: Cyclone | H6: NA | I6: 3.6 | J6: NA | K6: 3.63 | L6: Nationwide | M6: {=SUM( IFERROR( _xlfn.XLOOKUP( TRIM(_xlfn.TEXTSPLIT(nzcathist!L6, ",")), Sheet1!$A$2:$A$62, INDEX(Sheet1!$B$2:$AY$62, , MATCH(nzcathist!B6, Sheet1!$B$1:$AY$1, 0)) ), 0 ) )} -> 4567520
A7: 6 | B7: 2014 | C7: 1 | D7: 46076 | E7: 41693 | F7: Canterbury storm | G7: Storm | H7: Canterbury | I7: 4.8 | J7: NA | K7: 4.84 | L7: Christchurch,Ashburton,Timaru,Rangiora,Waimate,Temuka,Greymouth,Westport,Hokitika,Dunedin,Balclutha,Milton,Kaitangata | M7: {=SUM( IFERROR( _xlfn.XLOOKUP( TRIM(_xlfn.TEXTSPLIT(nzcathist!L7, ",")), Sheet1!$A$2:$A$62, INDEX(Sheet1!$B$2:$AY$62, , MATCH(nzcathist!B7, Sheet1!$B$1:$AY$1, 0)) ), 0 ) )} -> 577492.88
A8: 7 | B8: 2014 | C8: 1 | D8: 4-5Mar | E8: 41702 | F8: Canterbury and Lower North Island storm | G8: Storm | H8: Canterbury and Lower North Island | I8: 22.5 | J8: NA | K8: 22.71 | L8: Christchurch,Ashburton,Timaru,Rangiora,Waimate,Temuka,Wellington,Masterton,Carterton,Kapiti,Foxton,Palmerston North,Fielding,Marton,Wanganui | M8: {=SUM( IFERROR( _xlfn.XLOOKUP( TRIM(_xlfn.TEXTSPLIT(nzcathist!L8, ",")), Sheet1!$A$2:$A$62, INDEX(Sheet1!$B$2:$AY$62, , MATCH(nzcathist!B8, Sheet1!$B$1:$AY$1, 0)) ), 0 ) )} -> 1027982.1
A9: 8 | B9: 2013 | C9: 4 | D9: 14-16Oct | E9: 41592 | F9: Nationwide storm | G9: Storm | H9: Nationwide | I9: 12.4 | J9: NA | K9: 12.56 | L9: Nationwide | M9: {=SUM( IFERROR( _xlfn.XLOOKUP( TRIM(_xlfn.TEXTSPLIT(nzcathist!L9, ",")), Sheet1!$A$2:$A$62, INDEX(Sheet1!$B$2:$AY$62, , MATCH(nzcathist!B9, Sheet1!$B$1:$AY$1, 0)) ), 0 ) )} -> 4518520
A10: 9 | B10: 2013 | C10: 3 | D10: 11-12Sep | E10: 41528 | F10: Nationwide storm | G10: Storm | H10: Nationwide | I10: 74.5 | J10: NA | K10: 75.5 | L10: Nationwide | M10: {=SUM( IFERROR( _xlfn.XLOOKUP( TRIM(_xlfn.TEXTSPLIT(nzcathist!L10, ",")), Sheet1!$A$2:$A$62, INDEX(Sheet1!$B$2:$AY$62, , MATCH(nzcathist!B10, Sheet1!$B$1:$AY$1, 0)) ), 0 ) )} -> 4518520
A11: 10 | B11: 2013 | C11: 3 | D11: 46250 | E11: 41502 | F11: Cook Strait earthquake | G11: Earthquake | H11: Cook Strait | I11: 16.2 | J11: NA | K11: 16.42 | L11: Wellington,Masterton,Carterton,Kapiti,Foxton,Nelson,Blenheim,Christchurch,Ashburton,Rangiora | M11: {=SUM( IFERROR( _xlfn.XLOOKUP( TRIM(_xlfn.TEXTSPLIT(nzcathist!L11, ",")), Sheet1!$A$2:$A$62, INDEX(Sheet1!$B$2:$AY$62, , MATCH(nzcathist!B11, Sheet1!$B$1:$AY$1, 0)) ), 0 ) )} -> 947329.58
A12: 11 | B12: 2013 | C12: 3 | D12: 46224 | E12: 41476 | F12: Cook Strait earthquake | G12: Earthquake | H12: Cook Strait | I12: 14.9 | J12: NA | K12: 15.1 | L12: Wellington,Masterton,Carterton,Kapiti,Foxton,Nelson,Blenheim,Christchurch,Ashburton,Rangiora | M12: {=SUM( IFERROR( _xlfn.XLOOKUP( TRIM(_xlfn.TEXTSPLIT(nzcathist!L12, ",")), Sheet1!$A$2:$A$62, INDEX(Sheet1!$B$2:$AY$62, , MATCH(nzcathist!B12, Sheet1!$B$1:$AY$1, 0)) ), 0 ) )} -> 947329.58
A13: 12 | B13: 2013 | C13: 2 | D13: 20-22Jun | E13: 41445 | F13: Nationwide storms | G13: Storm | H13: Nationwide | I13: 39.3 | J13: NA | K13: 40.2 | L13: Nationwide | M13: {=SUM( IFERROR( _xlfn.XLOOKUP( TRIM(_xlfn.TEXTSPLIT(nzcathist!L13, ",")), Sheet1!$A$2:$A$62, INDEX(Sheet1!$B$2:$AY$62, , MATCH(nzcathist!B13, Sheet1!$B$1:$AY$1, 0)) ), 0 ) )} -> 4518520
A14: 13 | B14: 2013 | C14: 2 | D14: 4-7May | E14: 41429 | F14: North Island Floodsn | G14: Flood | H14: North Island | I14: 2.9 | J14: NA | K14: 2.97 | L14: Whangarei,Dargaville,Auckland,Pukekohe,Hamilton,Cambridge,Huntly,Te Awamutu,Te Kuiti,Tokoroa,Morrinsville,Waihi,Tauranga,Rotorua,Whakatane,Gisborne,Napier,Hastings,Wairoa,Waipukurau,Dannevirke,New Plymouth,Hawera,Waitara,Stratford,Eltham,Wanganui,Palmerston North,Fielding,Marton,Ohakune,Taumaranui,Wellington,Masterton,Carterton,Kapiti,Foxton | M14: {=SUM( IFERROR( _xlfn.XLOOKUP( TRIM(_xlfn.TEXTSPLIT(nzcathist!L14, ",")), Sheet1!$A$2:$A$62, INDEX(Sheet1!$B$2:$AY$62, , MATCH(nzcathist!B14, Sheet1!$B$1:$AY$1, 0)) ), 0 ) )} -> 2726947.1
A15: 14 | B15: 2013 | C15: 2 | D15: 19-22Apr | E15: 41383 | F15: Nelson,Bay of Plenty storm and floods | G15: Flood, Storm | H15: Nelson,Bay of Plenty | I15: 46.2 | J15: NA | K15: 47.26 | L15: Nelson,Blenheim,Tauranga,Rotorua,Whakatane | M15: {=SUM( IFERROR( _xlfn.XLOOKUP( TRIM(_xlfn.TEXTSPLIT(nzcathist!L15, ",")), Sheet1!$A$2:$A$62, INDEX(Sheet1!$B$2:$AY$62, , MATCH(nzcathist!B15, Sheet1!$B$1:$AY$1, 0)) ), 0 ) )} -> 292277.56
A16: 15 | B16: 2012 | C16: 4 | D16: 46362 | E16: 41249 | F16: Auckland Tornado | G16: Tornado | H16: Auckland | I16: 8.7 | J16: NA | K16: 8.95 | L16: Auckland,Pukekohe | M16: {=SUM( IFERROR( _xlfn.XLOOKUP( TRIM(_xlfn.TEXTSPLIT(nzcathist!L16, ",")), Sheet1!$A$2:$A$62, INDEX(Sheet1!$B$2:$AY$62, , MATCH(nzcathist!B16, Sheet1!$B$1:$AY$1, 0)) ), 0 ) )} -> 1368895.8
A17: 16 | B17: 2011 | C17: 1 | D17: 2010-2011 | E17: NA | F17: Canterbury Earthquake accumulated total | G17: Earthquake | H17: Canterbury | I17: 16500 | J17: NA | K17: 17320.68 | L17: Christchurch,Ashburton,Timaru,Rangiora,Waimate,Temuka,Nelson,Blenheim,Greymouth,Westport,Hokitika,Dunedin,Balclutha,Milton,Kaitangata | M17: {=SUM( IFERROR( _xlfn.XLOOKUP( TRIM(_xlfn.TEXTSPLIT(nzcathist!L17, ",")), Sheet1!$A$2:$A$62, INDEX(Sheet1!$B$2:$AY$62, , MATCH(nzcathist!B17, Sheet1!$B$1:$AY$1, 0)) ), 0 ) )} -> 657679.52
A18: 17 | B18: 2011 | C18: 1 | D18: 46051 | E18: 40572 | F18: Nelson,Bay of Plenty storm and floods | G18: Flood, Storm | H18: Nelson,Bay of Plenty | I18: 19.8 | J18: 20.11 | K18: 20.78 | L18: Nelson,Blenheim,Tauranga,Rotorua,Whakatane | M18: {=SUM( IFERROR( _xlfn.XLOOKUP( TRIM(_xlfn.TEXTSPLIT(nzcathist!L18, ",")), Sheet1!$A$2:$A$62, INDEX(Sheet1!$B$2:$AY$62, , MATCH(nzcathist!B18, Sheet1!$B$1:$AY$1, 0)) ), 0 ) )} -> 284114.79
A19: 18 | B19: 2011 | C19: 2 | D19: 26-27Apr | E19: 40659 | F19: Flooding, Hawkes Bay | G19: Flood | H19: Hawkes Bay | I19: 6.4 | J19: 6.45 | K19: 6.65 | L19: Napier,Hastings,Wairoa,Waipukurau,Dannevirke | M19: {=SUM( IFERROR( _xlfn.XLOOKUP( TRIM(_xlfn.TEXTSPLIT(nzcathist!L19, ",")), Sheet1!$A$2:$A$62, INDEX(Sheet1!$B$2:$AY$62, , MATCH(nzcathist!B19, Sheet1!$B$1:$AY$1, 0)) ), 0 ) )} -> 132934.02
A20: 19 | B20: 2011 | C20: 1 | D20: 46045 | E20: 40566 | F20: Flooding Mid-Upper North Island | G20: Flood | H20: Mid-Upper North Island | I20: 6.9 | J20: 7.01 | K20: 7.24 | L20: Auckland,Pukekohe,Hamilton,Cambridge,Huntly,Te Awamutu,Te Kuiti,Tokoroa,Morrinsville,Waihi,Tauranga,Rotorua,Whakatane | M20: {=SUM( IFERROR( _xlfn.XLOOKUP( TRIM(_xlfn.TEXTSPLIT(nzcathist!L20, ",")), Sheet1!$A$2:$A$62, INDEX(Sheet1!$B$2:$AY$62, , MATCH(nzcathist!B20, Sheet1!$B$1:$AY$1, 0)) ), 0 ) )} -> 1790879.8
A21: 20 | B21: 2011 | C21: 2 | D21: 46192 | E21: 40713 | F21: Taranaki tornados | G21: Tornado | H21: Taranaki | I21: 1.6 | J21: 1.6 | K21: 1.66 | L21: New Plymouth,Hawera,Waitara,Stratford,Eltham | M21: {=SUM( IFERROR( _xlfn.XLOOKUP( TRIM(_xlfn.TEXTSPLIT(nzcathist!L21, ",")), Sheet1!$A$2:$A$62, INDEX(Sheet1!$B$2:$AY$62, , MATCH(nzcathist!B21, Sheet1!$B$1:$AY$1, 0)) ), 0 ) )} -> 70506.387
A22: 21 | B22: 2011 | C22: 4 | D22: 15-16Dec | E22: 40892 | F22: Nelson Floods | G22: Flood | H22: Nelson | I22: 16.8 | J22: 16.8 | K22: 17.45 | L22: Nelson,Blenheim,Greymouth,Westport,Hokitika,Christchurch,Ashburton,Rangiora,Timaru,Waimate,Temuka | M22: {=SUM( IFERROR( _xlfn.XLOOKUP( TRIM(_xlfn.TEXTSPLIT(nzcathist!L22, ",")), Sheet1!$A$2:$A$62, INDEX(Sheet1!$B$2:$AY$62, , MATCH(nzcathist!B22, Sheet1!$B$1:$AY$1, 0)) ), 0 ) )} -> 541329.39
A23: 22 | B23: 2011 | C23: 2 | D23: 46145 | E23: 40666 | F23: Auckland tornado | G23: Tornado | H23: Auckland | I23: 6 | J23: 6.04 | K23: 6.24 | L23: Auckland,Pukekohe | M23: {=SUM( IFERROR( _xlfn.XLOOKUP( TRIM(_xlfn.TEXTSPLIT(nzcathist!L23, ",")), Sheet1!$A$2:$A$62, INDEX(Sheet1!$B$2:$AY$62, , MATCH(nzcathist!B23, Sheet1!$B$1:$AY$1, 0)) ), 0 ) )} -> 1344806.8
A24: 23 | B24: 2010 | C24: 2 | D24: 24-27May | E24: 40322 | F24: Flooding North , South Islands | G24: Flood | H24: North, South Islands | I24: 5.5 | J24: 5.8 | K24: 6.02 | L24: Nationwide | M24: {=SUM( IFERROR( _xlfn.XLOOKUP( TRIM(_xlfn.TEXTSPLIT(nzcathist!L24, ",")), Sheet1!$A$2:$A$62, INDEX(Sheet1!$B$2:$AY$62, , MATCH(nzcathist!B24, Sheet1!$B$1:$AY$1, 0)) ), 0 ) )} -> 4370060
A25: 24 | B25: 2010 | C25: 3 | D25: 46283 | E25: 40439 | F25: Southland Storm | G25: Storm | H25: Southland | I25: 49.3 | J25: 51.46 | K25: 53.38 | L25: Invercargill,Gore,Bluff,Dunedin,Balclutha,Milton,Kaitangata | M25: {=SUM( IFERROR( _xlfn.XLOOKUP( TRIM(_xlfn.TEXTSPLIT(nzcathist!L25, ",")), Sheet1!$A$2:$A$62, INDEX(Sheet1!$B$2:$AY$62, , MATCH(nzcathist!B25, Sheet1!$B$1:$AY$1, 0)) ), 0 ) )} -> 173059.06
A26: 25 | B26: 2010 | C26: 4 | D26: 13,14Oct | E26: 40464 | F26: Gisborne Flooding | G26: Flood | H26: Gisborne | I26: 0.25 | J26: 0.26 | K26: 0.26 | L26: Gisborne | M26: {=SUM( IFERROR( _xlfn.XLOOKUP( TRIM(_xlfn.TEXTSPLIT(nzcathist!L26, ",")), Sheet1!$A$2:$A$62, INDEX(Sheet1!$B$2:$AY$62, , MATCH(nzcathist!B26, Sheet1!$B$1:$AY$1, 0)) ), 0 ) )} -> 32479.447
A27: 26 | B27: 2010 | C27: 1 | D27: 46093 | E27: 40249 | F27: Wellington Thunderstorm | G27: Storm | H27: Wellington | I27: 1.2 | J27: 1.27 | K27: 1.32 | L27: Wellington,Masterton,Carterton,Kapiti,Foxton,Palmerston North,Fielding,Marton,Wanganui | M27: {=SUM( IFERROR( _xlfn.XLOOKUP( TRIM(_xlfn.TEXTSPLIT(nzcathist!L27, ",")), Sheet1!$A$2:$A$62, INDEX(Sheet1!$B$2:$AY$62, , MATCH(nzcathist!B27, Sheet1!$B$1:$AY$1, 0)) ), 0 ) )} -> 569151.28
A28: 27 | B28: 2010 | C28: 2 | D28: 46174 | E28: 40330 | F28: Flooding - Northland,Coromandel,Eastern BOP | G28: Flood | H28: Northland,Coromandel,Eastern BOP | I28: 12.5 | J28: 13.18 | K28: 13.68 | L28: Whangarei,Dargaville,Thames,Tauranga,Rotorua,Whakatane | M28: {=SUM( IFERROR( _xlfn.XLOOKUP( TRIM(_xlfn.TEXTSPLIT(nzcathist!L28, ",")), Sheet1!$A$2:$A$62, INDEX(Sheet1!$B$2:$AY$62, , MATCH(nzcathist!B28, Sheet1!$B$1:$AY$1, 0)) ), 0 ) )} -> 246400.31
A29: 28 | B29: 2009 | C29: 3 | D29: 46224 | E29: 40015 | F29: Taranaki Tornado | G29: Tornado | H29: Taranaki | I29: 0.5 | J29: 0.53 | K29: 0.55 | L29: New Plymouth,Hawera,Waitara,Stratford,Eltham | M29: {=SUM( IFERROR( _xlfn.XLOOKUP( TRIM(_xlfn.TEXTSPLIT(nzcathist!L29, ",")), Sheet1!$A$2:$A$62, INDEX(Sheet1!$B$2:$AY$62, , MATCH(nzcathist!B29, Sheet1!$B$1:$AY$1, 0)) ), 0 ) )} -> 70880.32
A30: 29 | B30: 2009 | C30: 3 | D30: 46218 | E30: 40009 | F30: Fiordland Earthquake | G30: Earthquake | H30: Fiordland | I30: 1.5 | J30: 1.6 | K30: 1.65 | L30: Invercargill,Gore,Bluff,Dunedin,Balclutha,Milton,Kaitangata,Christchurch,Ashburton,Timaru,Rangiora | M30: {=SUM( IFERROR( _xlfn.XLOOKUP( TRIM(_xlfn.TEXTSPLIT(nzcathist!L30, ",")), Sheet1!$A$2:$A$62, INDEX(Sheet1!$B$2:$AY$62, , MATCH(nzcathist!B30, Sheet1!$B$1:$AY$1, 0)) ), 0 ) )} -> 596204.74
A31: 30 | B31: 2009 | C31: 3 | D31: 11,12Jul | E31: 40005 | F31: North Island Storms | G31: Storm | H31: North Island | I31: 1.7 | J31: 1.82 | K31: 1.87 | L31: Whangarei,Dargaville,Auckland,Pukekohe,Hamilton,Cambridge,Huntly,Te Awamutu,Te Kuiti,Tokoroa,Morrinsville,Waihi,Tauranga,Rotorua,Whakatane,Gisborne,Napier,Hastings,Wairoa,Waipukurau,Dannevirke,New Plymouth,Hawera,Waitara,Stratford,Eltham,Wanganui,Palmerston North,Fielding,Marton,Ohakune,Taumaranui,Wellington,Masterton,Carterton,Kapiti,Foxton | M31: {=SUM( IFERROR( _xlfn.XLOOKUP( TRIM(_xlfn.TEXTSPLIT(nzcathist!L31, ",")), Sheet1!$A$2:$A$62, INDEX(Sheet1!$B$2:$AY$62, , MATCH(nzcathist!B31, Sheet1!$B$1:$AY$1, 0)) ), 0 ) )} -> 2593729.9
A32: 31 | B32: 2009 | C32: 2 | D32: 46153 | E32: 39944 | F32: Bay of Plenty Hail Storm | G32: Hailstorm | H32: Bay of Plenty | I32: 2.3 | J32: 2.47 | K32: 2.56 | L32: Tauranga,Rotorua,Whakatane | M32: {=SUM( IFERROR( _xlfn.XLOOKUP( TRIM(_xlfn.TEXTSPLIT(nzcathist!L32, ",")), Sheet1!$A$2:$A$62, INDEX(Sheet1!$B$2:$AY$62, , MATCH(nzcathist!B32, Sheet1!$B$1:$AY$1, 0)) ), 0 ) )} -> 188834.12
A33: 32 | B33: 2009 | C33: 3 | D33: 46207 | E33: 39998 | F33: Kaitaia Tornado | G33: Tornado | H33: Kaitaia | I33: 0.01 | J33: 0.01 | K33: 0.01 | L33: Whangarei,Dargaville | M33: {=SUM( IFERROR( _xlfn.XLOOKUP( TRIM(_xlfn.TEXTSPLIT(nzcathist!L33, ",")), Sheet1!$A$2:$A$62, INDEX(Sheet1!$B$2:$AY$62, , MATCH(nzcathist!B33, Sheet1!$B$1:$AY$1, 0)) ), 0 ) )} -> 54238.146
A34: 33 | B34: 2008 | C34: 3 | D34: 30-Jul-1-Aug | E34: 39659 | F34: Nationwide Storms | G34: Storm | H34: Nationwide | I34: 46.3 | J34: 50.29 | K34: 51.72 | L34: Nationwide | M34: {=SUM( IFERROR( _xlfn.XLOOKUP( TRIM(_xlfn.TEXTSPLIT(nzcathist!L34, ",")), Sheet1!$A$2:$A$62, INDEX(Sheet1!$B$2:$AY$62, , MATCH(nzcathist!B34, Sheet1!$B$1:$AY$1, 0)) ), 0 ) )} -> 4278160
A35: 34 | B35: 2008 | C35: 3 | D35: 46260 | E35: 39686 | F35: Flooding Nth Canterbury and Marlborough | G35: Flood | H35: North Canterbury and Marlborough | I35: 0.8 | J35: 0.87 | K35: 0.89 | L35: Christchurch,Ashburton,Rangiora,Timaru,Waimate,Temuka,Nelson,Blenheim,Greymouth,Westport,Hokitika | M35: {=SUM( IFERROR( _xlfn.XLOOKUP( TRIM(_xlfn.TEXTSPLIT(nzcathist!L35, ",")), Sheet1!$A$2:$A$62, INDEX(Sheet1!$B$2:$AY$62, , MATCH(nzcathist!B35, Sheet1!$B$1:$AY$1, 0)) ), 0 ) )} -> 529496.04
A36: 35 | B36: 2008 | C36: 3 | D36: 26-27-Jul | E36: 39655 | F36: North Island Storms | G36: Storm | H36: North Island | I36: 26.7 | J36: 29.02 | K36: 29.82 | L36: Whangarei,Dargaville,Auckland,Pukekohe,Hamilton,Cambridge,Huntly,Te Awamutu,Te Kuiti,Tokoroa,Morrinsville,Waihi,Tauranga,Rotorua,Whakatane,Gisborne,Napier,Hastings,Wairoa,Waipukurau,Dannevirke,New Plymouth,Hawera,Waitara,Stratford,Eltham,Wanganui,Palmerston North,Fielding,Marton,Ohakune,Taumaranui,Wellington,Masterton,Carterton,Kapiti,Foxton | M36: {=SUM( IFERROR( _xlfn.XLOOKUP( TRIM(_xlfn.TEXTSPLIT(nzcathist!L36, ",")), Sheet1!$A$2:$A$62, INDEX(Sheet1!$B$2:$AY$62, , MATCH(nzcathist!B36, Sheet1!$B$1:$AY$1, 0)) ), 0 ) )} -> 2561885.8
A37: 36 | B37: 2008 | C37: 3 | D37: 46259 | E37: 39685 | F37: Hastings Earthquake | G37: Earthquake | H37: Hastings | I37: 0.23 | J37: 0.25 | K37: 0.26 | L37: Hastings,Napier,Wairoa,Waipukurau,Dannevirke | M37: {=SUM( IFERROR( _xlfn.XLOOKUP( TRIM(_xlfn.TEXTSPLIT(nzcathist!L37, ",")), Sheet1!$A$2:$A$62, INDEX(Sheet1!$B$2:$AY$62, , MATCH(nzcathist!B37, Sheet1!$B$1:$AY$1, 0)) ), 0 ) )} -> 131813.47
A38: 37 | B38: 2008 | C38: 4 | D38: 46312 | E38: 39738 | F38: Cambridge Tornado | G38: Tornado | H38: Cambridge | I38: 1.03 | J38: 1.11 | K38: 1.16 | L38: Cambridge,Hamilton,Huntly,Te Awamutu,Morrinsville,Tokoroa | M38: {=SUM( IFERROR( _xlfn.XLOOKUP( TRIM(_xlfn.TEXTSPLIT(nzcathist!L38, ",")), Sheet1!$A$2:$A$62, INDEX(Sheet1!$B$2:$AY$62, , MATCH(nzcathist!B38, Sheet1!$B$1:$AY$1, 0)) ), 0 ) )} -> 235809.38
A39: 38 | B39: 2008 | C39: 4 | D39: 46343 | E39: 39769 | F39: Canterbury hail storm | G39: Hailstorm | H39: Canterbury | I39: 11.2 | J39: 12.07 | K39: 12.57 | L39: Christchurch,Ashburton,Timaru,Rangiora,Waimate,Temuka,Greymouth,Westport,Hokitika | M39: {=SUM( IFERROR( _xlfn.XLOOKUP( TRIM(_xlfn.TEXTSPLIT(nzcathist!L39, ",")), Sheet1!$A$2:$A$62, INDEX(Sheet1!$B$2:$AY$62, , MATCH(nzcathist!B39, Sheet1!$B$1:$AY$1, 0)) ), 0 ) )} -> 442911.58
A40: 39 | B40: 2007 | C40: 1 | D40: 46110 | E40: 39170 | F40: Storm event - Far North | G40: Storm | H40: Far North | I40: 12.5 | J40: 14.33 | K40: 14.89 | L40: Whangarei,Dargaville | M40: {=SUM( IFERROR( _xlfn.XLOOKUP( TRIM(_xlfn.TEXTSPLIT(nzcathist!L40, ",")), Sheet1!$A$2:$A$62, INDEX(Sheet1!$B$2:$AY$62, , MATCH(nzcathist!B40, Sheet1!$B$1:$AY$1, 0)) ), 0 ) )} -> 53615.665
...

Sheet Sheet1
A1: Town | B1: 1966 | C1: 1967 | D1: 1968 | E1: 1969 | F1: 1970 | G1: 1971 | H1: 1972 | I1: 1973 | J1: 1974 | K1: 1975 | L1: 1976 | M1: 1977 | N1: 1978 | O1: 1979 | P1: 1980 | Q1: 1981 | R1: 1982 | S1: 1983 | T1: 1984 | U1: 1985 | V1: 1986 | W1: 1987 | X1: 1988 | Y1: 1989 | Z1: 1990 | AA1: 1991 | AB1: 1992 | AC1: 1993 | AD1: 1994 | AE1: 1995 | AF1: 1996 | AG1: 1997 | AH1: 1998 | AI1: 1999 | AJ1: 2000 | AK1: 2001 | AL1: 2002 | AM1: 2003 | AN1: 2004 | AO1: 2005 | AP1: 2006 | AQ1: 2007 | AR1: 2008 | AS1: 2009 | AT1: 2010 | AU1: 2011 | AV1: 2012 | AW1: 2013 | AX1: 2014 | AY1: 2015
A2: Ashburton | B2: 13755 | C2: =$L2-($L2-$B2)*(9/10) -> 13923.6 | D2: =$L2-($L2-$B2)*(8/10) -> 14092.2 | E2: =$L2-($L2-$B2)*(7/10) -> 14260.8 | F2: =$L2-($L2-$B2)*(6/10) -> 14429.4 | G2: =$L2-($L2-$B2)*(5/10) -> 14598 | H2: =$L2-($L2-$B2)*(4/10) -> 14766.6 | I2: =$L2-($L2-$B2)*(3/10) -> 14935.2 | J2: =$L2-($L2-$B2)*(2/10) -> 15103.8 | K2: =$L2-($L2-$B2)*(1/10) -> 15272.4 | L2: 15441 | M2: =$V2-($V2-$L2)*(9/10) -> 15419.8 | N2: =$V2-($V2-$L2)*(8/10) -> 15398.6 | O2: =$V2-($V2-$L2)*(7/10) -> 15377.4 | P2: =$V2-($V2-$L2)*(6/10) -> 15356.2 | Q2: =$V2-($V2-$L2)*(5/10) -> 15335 | R2: =$V2-($V2-$L2)*(4/10) -> 15313.8 | S2: =$V2-($V2-$L2)*(3/10) -> 15292.6 | T2: =$V2-($V2-$L2)*(2/10) -> 15271.4 | U2: =$V2-($V2-$L2)*(1/10) -> 15250.2 | V2: 15229 | W2: =$AF2-($AF2-$V2)*(9/10) -> 15230.5 | X2: =$AF2-($AF2-$V2)*(8/10) -> 15232 | Y2: =$AF2-($AF2-$V2)*(7/10) -> 15233.5 | Z2: =$AF2-($AF2-$V2)*(6/10) -> 15235 | AA2: =$AF2-($AF2-$V2)*(5/10) -> 15236.5 | AB2: =$AF2-($AF2-$V2)*(4/10) -> 15238 | AC2: =$AF2-($AF2-$V2)*(3/10) -> 15239.5 | AD2: =$AF2-($AF2-$V2)*(2/10) -> 15241 | AE2: =$AF2-($AF2-$V2)*(1/10) -> 15242.5 | AF2: 15244 | AG2: =$AP2-($AP2-$AF2)*(9/10) -> 15343.6 | AH2: =$AP2-($AP2-$AF2)*(8/10) -> 15443.2 | AI2: =$AP2-($AP2-$AF2)*(7/10) -> 15542.8 | AJ2: =$AP2-($AP2-$AF2)*(6/10) -> 15642.4 | AK2: =$AP2-($AP2-$AF2)*(5/10) -> 15742 | AL2: =$AP2-($AP2-$AF2)*(4/10) -> 15841.6 | AM2: =$AP2-($AP2-$AF2)*(3/10) -> 15941.2 | AN2: =$AP2-($AP2-$AF2)*(2/10) -> 16040.8 | AO2: =$AP2-($AP2-$AF2)*(1/10) -> 16140.4 | AP2: 16240 | AQ2: =AP2*(1+((AP2/AO2)-1)) -> 16340.215 | AR2: =AQ2*(1+((AQ2/AP2)-1)) -> 16441.048 | AS2: =AR2*(1+((AR2/AQ2)-1)) -> 16542.503 | AT2: =AS2*(1+((AS2/AR2)-1)) -> 16644.584 | AU2: =AT2*(1+((AT2/AS2)-1)) -> 16747.295 | AV2: =AU2*(1+((AU2/AT2)-1)) -> 16850.641 | AW2: =AV2*(1+((AV2/AU2)-1)) -> 16954.623 | AX2: =AW2*(1+((AW2/AV2)-1)) -> 17059.248 | AY2: =AX2*(1+((AX2/AW2)-1)) -> 17164.518
A3: Auckland | B3: 548293 | C3: =$L3-($L3-$B3)*(9/10) -> 567742.3 | D3: =$L3-($L3-$B3)*(8/10) -> 587191.6 | E3: =$L3-($L3-$B3)*(7/10) -> 606640.9 | F3: =$L3-($L3-$B3)*(6/10) -> 626090.2 | G3: =$L3-($L3-$B3)*(5/10) -> 645539.5 | H3: =$L3-($L3-$B3)*(4/10) -> 664988.8 | I3: =$L3-($L3-$B3)*(3/10) -> 684438.1 | J3: =$L3-($L3-$B3)*(2/10) -> 703887.4 | K3: =$L3-($L3-$B3)*(1/10) -> 723336.7 | L3: 742786 | M3: =$V3-($V3-$L3)*(9/10) -> 750582.8 | N3: =$V3-($V3-$L3)*(8/10) -> 758379.6 | O3: =$V3-($V3-$L3)*(7/10) -> 766176.4 | P3: =$V3-($V3-$L3)*(6/10) -> 773973.2 | Q3: =$V3-($V3-$L3)*(5/10) -> 781770 | R3: =$V3-($V3-$L3)*(4/10) -> 789566.8 | S3: =$V3-($V3-$L3)*(3/10) -> 797363.6 | T3: =$V3-($V3-$L3)*(2/10) -> 805160.4 | U3: =$V3-($V3-$L3)*(1/10) -> 812957.2 | V3: 820754 | W3: =$AF3-($AF3-$V3)*(9/10) -> 838472.6 | X3: =$AF3-($AF3-$V3)*(8/10) -> 856191.2 | Y3: =$AF3-($AF3-$V3)*(7/10) -> 873909.8 | Z3: =$AF3-($AF3-$V3)*(6/10) -> 891628.4 | AA3: =$AF3-($AF3-$V3)*(5/10) -> 909347 | AB3: =$AF3-($AF3-$V3)*(4/10) -> 927065.6 | AC3: =$AF3-($AF3-$V3)*(3/10) -> 944784.2 | AD3: =$AF3-($AF3-$V3)*(2/10) -> 962502.8 | AE3: =$AF3-($AF3-$V3)*(1/10) -> 980221.4 | AF3: 997940 | AG3: =$AP3-($AP3-$AF3)*(9/10) -> 1018955.4 | AH3: =$AP3-($AP3-$AF3)*(8/10) -> 1039970.8 | AI3: =$AP3-($AP3-$AF3)*(7/10) -> 1060986.2 | AJ3: =$AP3-($AP3-$AF3)*(6/10) -> 1082001.6 | AK3: =$AP3-($AP3-$AF3)*(5/10) -> 1103017 | AL3: =$AP3-($AP3-$AF3)*(4/10) -> 1124032.4 | AM3: =$AP3-($AP3-$AF3)*(3/10) -> 1145047.8 | AN3: =$AP3-($AP3-$AF3)*(2/10) -> 1166063.2 | AO3: =$AP3-($AP3-$AF3)*(1/10) -> 1187078.6 | AP3: 1208094 | AQ3: =AP3*(1+((AP3/AO3)-1)) -> 1229481.4 | AR3: =AQ3*(1+((AQ3/AP3)-1)) -> 1251247.5 | AS3: =AR3*(1+((AR3/AQ3)-1)) -> 1273398.9 | AT3: =AS3*(1+((AS3/AR3)-1)) -> 1295942.5 | AU3: =AT3*(1+((AT3/AS3)-1)) -> 1318885.2 | AV3: =AU3*(1+((AU3/AT3)-1)) -> 1342234 | AW3: =AV3*(1+((AV3/AU3)-1)) -> 1365996.2 | AX3: =AW3*(1+((AW3/AV3)-1)) -> 1390179.1 | AY3: =AX3*(1+((AX3/AW3)-1)) -> 1414790
A4: Balclutha | B4: 4419 | C4: =$L4-($L4-$B4)*(9/10) -> 4451.1 | D4: =$L4-($L4-$B4)*(8/10) -> 4483.2 | E4: =$L4-($L4-$B4)*(7/10) -> 4515.3 | F4: =$L4-($L4-$B4)*(6/10) -> 4547.4 | G4: =$L4-($L4-$B4)*(5/10) -> 4579.5 | H4: =$L4-($L4-$B4)*(4/10) -> 4611.6 | I4: =$L4-($L4-$B4)*(3/10) -> 4643.7 | J4: =$L4-($L4-$B4)*(2/10) -> 4675.8 | K4: =$L4-($L4-$B4)*(1/10) -> 4707.9 | L4: 4740 | M4: =$V4-($V4-$L4)*(9/10) -> 4688.7 | N4: =$V4-($V4-$L4)*(8/10) -> 4637.4 | O4: =$V4-($V4-$L4)*(7/10) -> 4586.1 | P4: =$V4-($V4-$L4)*(6/10) -> 4534.8 | Q4: =$V4-($V4-$L4)*(5/10) -> 4483.5 | R4: =$V4-($V4-$L4)*(4/10) -> 4432.2 | S4: =$V4-($V4-$L4)*(3/10) -> 4380.9 | T4: =$V4-($V4-$L4)*(2/10) -> 4329.6 | U4: =$V4-($V4-$L4)*(1/10) -> 4278.3 | V4: 4227 | W4: =$AF4-($AF4-$V4)*(9/10) -> 4185.1 | X4: =$AF4-($AF4-$V4)*(8/10) -> 4143.2 | Y4: =$AF4-($AF4-$V4)*(7/10) -> 4101.3 | Z4: =$AF4-($AF4-$V4)*(6/10) -> 4059.4 | AA4: =$AF4-($AF4-$V4)*(5/10) -> 4017.5 | AB4: =$AF4-($AF4-$V4)*(4/10) -> 3975.6 | AC4: =$AF4-($AF4-$V4)*(3/10) -> 3933.7 | AD4: =$AF4-($AF4-$V4)*(2/10) -> 3891.8 | AE4: =$AF4-($AF4-$V4)*(1/10) -> 3849.9 | AF4: 3808 | AG4: =$AP4-($AP4-$AF4)*(9/10) -> 3791.6 | AH4: =$AP4-($AP4-$AF4)*(8/10) -> 3775.2 | AI4: =$AP4-($AP4-$AF4)*(7/10) -> 3758.8 | AJ4: =$AP4-($AP4-$AF4)*(6/10) -> 3742.4 | AK4: =$AP4-($AP4-$AF4)*(5/10) -> 3726 | AL4: =$AP4-($AP4-$AF4)*(4/10) -> 3709.6 | AM4: =$AP4-($AP4-$AF4)*(3/10) -> 3693.2 | AN4: =$AP4-($AP4-$AF4)*(2/10) -> 3676.8 | AO4: =$AP4-($AP4-$AF4)*(1/10) -> 3660.4 | AP4: 3644 | AQ4: =AP4*(1+((AP4/AO4)-1)) -> 3627.6735 | AR4: =AQ4*(1+((AQ4/AP4)-1)) -> 3611.4201 | AS4: =AR4*(1+((AR4/AQ4)-1)) -> 3595.2396 | AT4: =AS4*(1+((AS4/AR4)-1)) -> 3579.1315 | AU4: =AT4*(1+((AT4/AS4)-1)) -> 3563.0956 | AV4: =AU4*(1+((AU4/AT4)-1)) -> 3547.1316 | AW4: =AV4*(1+((AV4/AU4)-1)) -> 3531.2391 | AX4: =AW4*(1+((AW4/AV4)-1)) -> 3515.4178 | AY4: =AX4*(1+((AX4/AW4)-1)) -> 3499.6673
A5: Blenheim | B5: 16405 | C5: =$L5-($L5-$B5)*(9/10) -> 16889.9 | D5: =$L5-($L5-$B5)*(8/10) -> 17374.8 | E5: =$L5-($L5-$B5)*(7/10) -> 17859.7 | F5: =$L5-($L5-$B5)*(6/10) -> 18344.6 | G5: =$L5-($L5-$B5)*(5/10) -> 18829.5 | H5: =$L5-($L5-$B5)*(4/10) -> 19314.4 | I5: =$L5-($L5-$B5)*(3/10) -> 19799.3 | J5: =$L5-($L5-$B5)*(2/10) -> 20284.2 | K5: =$L5-($L5-$B5)*(1/10) -> 20769.1 | L5: 21254 | M5: =$V5-($V5-$L5)*(9/10) -> 21396.7 | N5: =$V5-($V5-$L5)*(8/10) -> 21539.4 | O5: =$V5-($V5-$L5)*(7/10) -> 21682.1 | P5: =$V5-($V5-$L5)*(6/10) -> 21824.8 | Q5: =$V5-($V5-$L5)*(5/10) -> 21967.5 | R5: =$V5-($V5-$L5)*(4/10) -> 22110.2 | S5: =$V5-($V5-$L5)*(3/10) -> 22252.9 | T5: =$V5-($V5-$L5)*(2/10) -> 22395.6 | U5: =$V5-($V5-$L5)*(1/10) -> 22538.3 | V5: 22681 | W5: =$AF5-($AF5-$V5)*(9/10) -> 23000.4 | X5: =$AF5-($AF5-$V5)*(8/10) -> 23319.8 | Y5: =$AF5-($AF5-$V5)*(7/10) -> 23639.2 | Z5: =$AF5-($AF5-$V5)*(6/10) -> 23958.6 | AA5: =$AF5-($AF5-$V5)*(5/10) -> 24278 | AB5: =$AF5-($AF5-$V5)*(4/10) -> 24597.4 | AC5: =$AF5-($AF5-$V5)*(3/10) -> 24916.8 | AD5: =$AF5-($AF5-$V5)*(2/10) -> 25236.2 | AE5: =$AF5-($AF5-$V5)*(1/10) -> 25555.6 | AF5: 25875 | AG5: =$AP5-($AP5-$AF5)*(9/10) -> 26140.2 | AH5: =$AP5-($AP5-$AF5)*(8/10) -> 26405.4 | AI5: =$AP5-($AP5-$AF5)*(7/10) -> 26670.6 | AJ5: =$AP5-($AP5-$AF5)*(6/10) -> 26935.8 | AK5: =$AP5-($AP5-$AF5)*(5/10) -> 27201 | AL5: =$AP5-($AP5-$AF5)*(4/10) -> 27466.2 | AM5: =$AP5-($AP5-$AF5)*(3/10) -> 27731.4 | AN5: =$AP5-($AP5-$AF5)*(2/10) -> 27996.6 | AO5: =$AP5-($AP5-$AF5)*(1/10) -> 28261.8 | AP5: 28527 | AQ5: =AP5*(1+((AP5/AO5)-1)) -> 28794.689 | AR5: =AQ5*(1+((AQ5/AP5)-1)) -> 29064.889 | AS5: =AR5*(1+((AR5/AQ5)-1)) -> 29337.625 | AT5: =AS5*(1+((AS5/AR5)-1)) -> 29612.92 | AU5: =AT5*(1+((AT5/AS5)-1)) -> 29890.799 | AV5: =AU5*(1+((AU5/AT5)-1)) -> 30171.285 | AW5: =AV5*(1+((AV5/AU5)-1)) -> 30454.403 | AX5: =AW5*(1+((AW5/AV5)-1)) -> 30740.177 | AY5: =AX5*(1+((AX5/AW5)-1)) -> 31028.634
A6: Bluff | B6: 3279 | C6: =$L6-($L6-$B6)*(9/10) -> 3252.7 | D6: =$L6-($L6-$B6)*(8/10) -> 3226.4 | E6: =$L6-($L6-$B6)*(7/10) -> 3200.1 | F6: =$L6-($L6-$B6)*(6/10) -> 3173.8 | G6: =$L6-($L6-$B6)*(5/10) -> 3147.5 | H6: =$L6-($L6-$B6)*(4/10) -> 3121.2 | I6: =$L6-($L6-$B6)*(3/10) -> 3094.9 | J6: =$L6-($L6-$B6)*(2/10) -> 3068.6 | K6: =$L6-($L6-$B6)*(1/10) -> 3042.3 | L6: 3016 | M6: =$V6-($V6-$L6)*(9/10) -> 2968.1 | N6: =$V6-($V6-$L6)*(8/10) -> 2920.2 | O6: =$V6-($V6-$L6)*(7/10) -> 2872.3 | P6: =$V6-($V6-$L6)*(6/10) -> 2824.4 | Q6: =$V6-($V6-$L6)*(5/10) -> 2776.5 | R6: =$V6-($V6-$L6)*(4/10) -> 2728.6 | S6: =$V6-($V6-$L6)*(3/10) -> 2680.7 | T6: =$V6-($V6-$L6)*(2/10) -> 2632.8 | U6: =$V6-($V6-$L6)*(1/10) -> 2584.9 | V6: 2537 | W6: =$AF6-($AF6-$V6)*(9/10) -> 2484.4 | X6: =$AF6-($AF6-$V6)*(8/10) -> 2431.8 | Y6: =$AF6-($AF6-$V6)*(7/10) -> 2379.2 | Z6: =$AF6-($AF6-$V6)*(6/10) -> 2326.6 | AA6: =$AF6-($AF6-$V6)*(5/10) -> 2274 | AB6: =$AF6-($AF6-$V6)*(4/10) -> 2221.4 | AC6: =$AF6-($AF6-$V6)*(3/10) -> 2168.8 | AD6: =$AF6-($AF6-$V6)*(2/10) -> 2116.2 | AE6: =$AF6-($AF6-$V6)*(1/10) -> 2063.6 | AF6: 2011 | AG6: =$AP6-($AP6-$AF6)*(9/10) -> 1974.3 | AH6: =$AP6-($AP6-$AF6)*(8/10) -> 1937.6 | AI6: =$AP6-($AP6-$AF6)*(7/10) -> 1900.9 | AJ6: =$AP6-($AP6-$AF6)*(6/10) -> 1864.2 | AK6: =$AP6-($AP6-$AF6)*(5/10) -> 1827.5 | AL6: =$AP6-($AP6-$AF6)*(4/10) -> 1790.8 | AM6: =$AP6-($AP6-$AF6)*(3/10) -> 1754.1 | AN6: =$AP6-($AP6-$AF6)*(2/10) -> 1717.4 | AO6: =$AP6-($AP6-$AF6)*(1/10) -> 1680.7 | AP6: 1644 | AQ6: =AP6*(1+((AP6/AO6)-1)) -> 1608.1014 | AR6: =AQ6*(1+((AQ6/AP6)-1)) -> 1572.9867 | AS6: =AR6*(1+((AR6/AQ6)-1)) -> 1538.6387 | AT6: =AS6*(1+((AS6/AR6)-1)) -> 1505.0408 | AU6: =AT6*(1+((AT6/AS6)-1)) -> 1472.1765 | AV6: =AU6*(1+((AU6/AT6)-1)) -> 1440.0298 | AW6: =AV6*(1+((AV6/AU6)-1)) -> 1408.5851 | AX6: =AW6*(1+((AW6/AV6)-1)) -> 1377.8271 | AY6: =AX6*(1+((AX6/AW6)-1)) -> 1347.7407
A7: Cambridge | B7: 5962 | C7: =$L7-($L7-$B7)*(9/10) -> 6149.9 | D7: =$L7-($L7-$B7)*(8/10) -> 6337.8 | E7: =$L7-($L7-$B7)*(7/10) -> 6525.7 | F7: =$L7-($L7-$B7)*(6/10) -> 6713.6 | G7: =$L7-($L7-$B7)*(5/10) -> 6901.5 | H7: =$L7-($L7-$B7)*(4/10) -> 7089.4 | I7: =$L7-($L7-$B7)*(3/10) -> 7277.3 | J7: =$L7-($L7-$B7)*(2/10) -> 7465.2 | K7: =$L7-($L7-$B7)*(1/10) -> 7653.1 | L7: 7841 | M7: =$V7-($V7-$L7)*(9/10) -> 8071.4 | N7: =$V7-($V7-$L7)*(8/10) -> 8301.8 | O7: =$V7-($V7-$L7)*(7/10) -> 8532.2 | P7: =$V7-($V7-$L7)*(6/10) -> 8762.6 | Q7: =$V7-($V7-$L7)*(5/10) -> 8993 | R7: =$V7-($V7-$L7)*(4/10) -> 9223.4 | S7: =$V7-($V7-$L7)*(3/10) -> 9453.8 | T7: =$V7-($V7-$L7)*(2/10) -> 9684.2 | U7: =$V7-($V7-$L7)*(1/10) -> 9914.6 | V7: 10145 | W7: =$AF7-($AF7-$V7)*(9/10) -> 10272.3 | X7: =$AF7-($AF7-$V7)*(8/10) -> 10399.6 | Y7: =$AF7-($AF7-$V7)*(7/10) -> 10526.9 | Z7: =$AF7-($AF7-$V7)*(6/10) -> 10654.2 | AA7: =$AF7-($AF7-$V7)*(5/10) -> 10781.5 | AB7: =$AF7-($AF7-$V7)*(4/10) -> 10908.8 | AC7: =$AF7-($AF7-$V7)*(3/10) -> 11036.1 | AD7: =$AF7-($AF7-$V7)*(2/10) -> 11163.4 | AE7: =$AF7-($AF7-$V7)*(1/10) -> 11290.7 | AF7: 11418 | AG7: =$AP7-($AP7-$AF7)*(9/10) -> 11530.9 | AH7: =$AP7-($AP7-$AF7)*(8/10) -> 11643.8 | AI7: =$AP7-($AP7-$AF7)*(7/10) -> 11756.7 | AJ7: =$AP7-($AP7-$AF7)*(6/10) -> 11869.6 | AK7: =$AP7-($AP7-$AF7)*(5/10) -> 11982.5 | AL7: =$AP7-($AP7-$AF7)*(4/10) -> 12095.4 | AM7: =$AP7-($AP7-$AF7)*(3/10) -> 12208.3 | AN7: =$AP7-($AP7-$AF7)*(2/10) -> 12321.2 | AO7: =$AP7-($AP7-$AF7)*(1/10) -> 12434.1 | AP7: 12547 | AQ7: =AP7*(1+((AP7/AO7)-1)) -> 12660.925 | AR7: =AQ7*(1+((AQ7/AP7)-1)) -> 12775.885 | AS7: =AR7*(1+((AR7/AQ7)-1)) -> 12891.888 | AT7: =AS7*(1+((AS7/AR7)-1)) -> 13008.945 | AU7: =AT7*(1+((AT7/AS7)-1)) -> 13127.064 | AV7: =AU7*(1+((AU7/AT7)-1)) -> 13246.256 | AW7: =AV7*(1+((AV7/AU7)-1)) -> 13366.53 | AX7: =AW7*(1+((AW7/AV7)-1)) -> 13487.897 | AY7: =AX7*(1+((AX7/AW7)-1)) -> 13610.365
A8: Carterton | B8: 3536 | C8: =$L8-($L8-$B8)*(9/10) -> 3580.9 | D8: =$L8-($L8-$B8)*(8/10) -> 3625.8 | E8: =$L8-($L8-$B8)*(7/10) -> 3670.7 | F8: =$L8-($L8-$B8)*(6/10) -> 3715.6 | G8: =$L8-($L8-$B8)*(5/10) -> 3760.5 | H8: =$L8-($L8-$B8)*(4/10) -> 3805.4 | I8: =$L8-($L8-$B8)*(3/10) -> 3850.3 | J8: =$L8-($L8-$B8)*(2/10) -> 3895.2 | K8: =$L8-($L8-$B8)*(1/10) -> 3940.1 | L8: 3985 | M8: =$V8-($V8-$L8)*(9/10) -> 3976.7 | N8: =$V8-($V8-$L8)*(8/10) -> 3968.4 | O8: =$V8-($V8-$L8)*(7/10) -> 3960.1 | P8: =$V8-($V8-$L8)*(6/10) -> 3951.8 | Q8: =$V8-($V8-$L8)*(5/10) -> 3943.5 | R8: =$V8-($V8-$L8)*(4/10) -> 3935.2 | S8: =$V8-($V8-$L8)*(3/10) -> 3926.9 | T8: =$V8-($V8-$L8)*(2/10) -> 3918.6 | U8: =$V8-($V8-$L8)*(1/10) -> 3910.3 | V8: 3902 | W8: =$AF8-($AF8-$V8)*(9/10) -> 3908.6 | X8: =$AF8-($AF8-$V8)*(8/10) -> 3915.2 | Y8: =$AF8-($AF8-$V8)*(7/10) -> 3921.8 | Z8: =$AF8-($AF8-$V8)*(6/10) -> 3928.4 | AA8: =$AF8-($AF8-$V8)*(5/10) -> 3935 | AB8: =$AF8-($AF8-$V8)*(4/10) -> 3941.6 | AC8: =$AF8-($AF8-$V8)*(3/10) -> 3948.2 | AD8: =$AF8-($AF8-$V8)*(2/10) -> 3954.8 | AE8: =$AF8-($AF8-$V8)*(1/10) -> 3961.4 | AF8: 3968 | AG8: =$AP8-($AP8-$AF8)*(9/10) -> 3958.9 | AH8: =$AP8-($AP8-$AF8)*(8/10) -> 3949.8 | AI8: =$AP8-($AP8-$AF8)*(7/10) -> 3940.7 | AJ8: =$AP8-($AP8-$AF8)*(6/10) -> 3931.6 | AK8: =$AP8-($AP8-$AF8)*(5/10) -> 3922.5 | AL8: =$AP8-($AP8-$AF8)*(4/10) -> 3913.4 | AM8: =$AP8-($AP8-$AF8)*(3/10) -> 3904.3 | AN8: =$AP8-($AP8-$AF8)*(2/10) -> 3895.2 | AO8: =$AP8-($AP8-$AF8)*(1/10) -> 3886.1 | AP8: 3877 | AQ8: =AP8*(1+((AP8/AO8)-1)) -> 3867.9213 | AR8: =AQ8*(1+((AQ8/AP8)-1)) -> 3858.8639 | AS8: =AR8*(1+((AR8/AQ8)-1)) -> 3849.8277 | AT8: =AS8*(1+((AS8/AR8)-1)) -> 3840.8126 | AU8: =AT8*(1+((AT8/AS8)-1)) -> 3831.8186 | AV8: =AU8*(1+((AU8/AT8)-1)) -> 3822.8458 | AW8: =AV8*(1+((AV8/AU8)-1)) -> 3813.8939 | AX8: =AW8*(1+((AW8/AV8)-1)) -> 3804.963 | AY8: =AX8*(1+((AX8/AW8)-1)) -> 3796.053
A9: Christchurch | B9: 247248 | C9: =$L9-($L9-$B9)*(9/10) -> 252052.8 | D9: =$L9-($L9-$B9)*(8/10) -> 256857.6 | E9: =$L9-($L9-$B9)*(7/10) -> 261662.4 | F9: =$L9-($L9-$B9)*(6/10) -> 266467.2 | G9: =$L9-($L9-$B9)*(5/10) -> 271272 | H9: =$L9-($L9-$B9)*(4/10) -> 276076.8 | I9: =$L9-($L9-$B9)*(3/10) -> 280881.6 | J9: =$L9-($L9-$B9)*(2/10) -> 285686.4 | K9: =$L9-($L9-$B9)*(1/10) -> 290491.2 | L9: 295296 | M9: =$V9-($V9-$L9)*(9/10) -> 295703.7 | N9: =$V9-($V9-$L9)*(8/10) -> 296111.4 | O9: =$V9-($V9-$L9)*(7/10) -> 296519.1 | P9: =$V9-($V9-$L9)*(6/10) -> 296926.8 | Q9: =$V9-($V9-$L9)*(5/10) -> 297334.5 | R9: =$V9-($V9-$L9)*(4/10) -> 297742.2 | S9: =$V9-($V9-$L9)*(3/10) -> 298149.9 | T9: =$V9-($V9-$L9)*(2/10) -> 298557.6 | U9: =$V9-($V9-$L9)*(1/10) -> 298965.3 | V9: 299373 | W9: =$AF9-($AF9-$V9)*(9/10) -> 302580 | X9: =$AF9-($AF9-$V9)*(8/10) -> 305787 | Y9: =$AF9-($AF9-$V9)*(7/10) -> 308994 | Z9: =$AF9-($AF9-$V9)*(6/10) -> 312201 | AA9: =$AF9-($AF9-$V9)*(5/10) -> 315408 | AB9: =$AF9-($AF9-$V9)*(4/10) -> 318615 | AC9: =$AF9-($AF9-$V9)*(3/10) -> 321822 | AD9: =$AF9-($AF9-$V9)*(2/10) -> 325029 | AE9: =$AF9-($AF9-$V9)*(1/10) -> 328236 | AF9: 331443 | AG9: =$AP9-($AP9-$AF9)*(9/10) -> 334375.5 | AH9: =$AP9-($AP9-$AF9)*(8/10) -> 337308 | AI9: =$AP9-($AP9-$AF9)*(7/10) -> 340240.5 | AJ9: =$AP9-($AP9-$AF9)*(6/10) -> 343173 | AK9: =$AP9-($AP9-$AF9)*(5/10) -> 346105.5 | AL9: =$AP9-($AP9-$AF9)*(4/10) -> 349038 | AM9: =$AP9-($AP9-$AF9)*(3/10) -> 351970.5 | AN9: =$AP9-($AP9-$AF9)*(2/10) -> 354903 | AO9: =$AP9-($AP9-$AF9)*(1/10) -> 357835.5 | AP9: 360768 | AQ9: =AP9*(1+((AP9/AO9)-1)) -> 363724.53 | AR9: =AQ9*(1+((AQ9/AP9)-1)) -> 366705.29 | AS9: =AR9*(1+((AR9/AQ9)-1)) -> 369710.48 | AT9: =AS9*(1+((AS9/AR9)-1)) -> 372740.3 | AU9: =AT9*(1+((AT9/AS9)-1)) -> 375794.95 | AV9: =AU9*(1+((AU9/AT9)-1)) -> 378874.63 | AW9: =AV9*(1+((AV9/AU9)-1)) -> 381979.54 | AX9: =AW9*(1+((AW9/AV9)-1)) -> 385109.91 | AY9: =AX9*(1+((AX9/AW9)-1)) -> 388265.92
A10: Dannevirke | B10: 5728 | C10: =$L10-($L10-$B10)*(9/10) -> 5719 | D10: =$L10-($L10-$B10)*(8/10) -> 5710 | E10: =$L10-($L10-$B10)*(7/10) -> 5701 | F10: =$L10-($L10-$B10)*(6/10) -> 5692 | G10: =$L10-($L10-$B10)*(5/10) -> 5683 | H10: =$L10-($L10-$B10)*(4/10) -> 5674 | I10: =$L10-($L10-$B10)*(3/10) -> 5665 | J10: =$L10-($L10-$B10)*(2/10) -> 5656 | K10: =$L10-($L10-$B10)*(1/10) -> 5647 | L10: 5638 | M10: =$V10-($V10-$L10)*(9/10) -> 5661.5 | N10: =$V10-($V10-$L10)*(8/10) -> 5685 | O10: =$V10-($V10-$L10)*(7/10) -> 5708.5 | P10: =$V10-($V10-$L10)*(6/10) -> 5732 | Q10: =$V10-($V10-$L10)*(5/10) -> 5755.5 | R10: =$V10-($V10-$L10)*(4/10) -> 5779 | S10: =$V10-($V10-$L10)*(3/10) -> 5802.5 | T10: =$V10-($V10-$L10)*(2/10) -> 5826 | U10: =$V10-($V10-$L10)*(1/10) -> 5849.5 | V10: 5873 | W10: =$AF10-($AF10-$V10)*(9/10) -> 5820.1 | X10: =$AF10-($AF10-$V10)*(8/10) -> 5767.2 | Y10: =$AF10-($AF10-$V10)*(7/10) -> 5714.3 | Z10: =$AF10-($AF10-$V10)*(6/10) -> 5661.4 | AA10: =$AF10-($AF10-$V10)*(5/10) -> 5608.5 | AB10: =$AF10-($AF10-$V10)*(4/10) -> 5555.6 | AC10: =$AF10-($AF10-$V10)*(3/10) -> 5502.7 | AD10: =$AF10-($AF10-$V10)*(2/10) -> 5449.8 | AE10: =$AF10-($AF10-$V10)*(1/10) -> 5396.9 | AF10: 5344 | AG10: =$AP10-($AP10-$AF10)*(9/10) -> 5322 | AH10: =$AP10-($AP10-$AF10)*(8/10) -> 5300 | AI10: =$AP10-($AP10-$AF10)*(7/10) -> 5278 | AJ10: =$AP10-($AP10-$AF10)*(6/10) -> 5256 | AK10: =$AP10-($AP10-$AF10)*(5/10) -> 5234 | AL10: =$AP10-($AP10-$AF10)*(4/10) -> 5212 | AM10: =$AP10-($AP10-$AF10)*(3/10) -> 5190 | AN10: =$AP10-($AP10-$AF10)*(2/10) -> 5168 | AO10: =$AP10-($AP10-$AF10)*(1/10) -> 5146 | AP10: 5124 | AQ10: =AP10*(1+((AP10/AO10)-1)) -> 5102.0941 | AR10: =AQ10*(1+((AQ10/AP10)-1)) -> 5080.2818 | AS10: =AR10*(1+((AR10/AQ10)-1)) -> 5058.5627 | AT10: =AS10*(1+((AS10/AR10)-1)) -> 5036.9365 | AU10: =AT10*(1+((AT10/AS10)-1)) -> 5015.4028 | AV10: =AU10*(1+((AU10/AT10)-1)) -> 4993.9611 | AW10: =AV10*(1+((AV10/AU10)-1)) -> 4972.6111 | AX10: =AW10*(1+((AW10/AV10)-1)) -> 4951.3524 | AY10: =AX10*(1+((AX10/AW10)-1)) -> 4930.1845
A11: Dargaville | B11: 3902 | C11: =$L11-($L11-$B11)*(9/10) -> 3967.7 | D11: =$L11-($L11-$B11)*(8/10) -> 4033.4 | E11: =$L11-($L11-$B11)*(7/10) -> 4099.1 | F11: =$L11-($L11-$B11)*(6/10) -> 4164.8 | G11: =$L11-($L11-$B11)*(5/10) -> 4230.5 | H11: =$L11-($L11-$B11)*(4/10) -> 4296.2 | I11: =$L11-($L11-$B11)*(3/10) -> 4361.9 | J11: =$L11-($L11-$B11)*(2/10) -> 4427.6 | K11: =$L11-($L11-$B11)*(1/10) -> 4493.3 | L11: 4559 | M11: =$V11-($V11-$L11)*(9/10) -> 4589 | N11: =$V11-($V11-$L11)*(8/10) -> 4619 | O11: =$V11-($V11-$L11)*(7/10) -> 4649 | P11: =$V11-($V11-$L11)*(6/10) -> 4679 | Q11: =$V11-($V11-$L11)*(5/10) -> 4709 | R11: =$V11-($V11-$L11)*(4/10) -> 4739 | S11: =$V11-($V11-$L11)*(3/10) -> 4769 | T11: =$V11-($V11-$L11)*(2/10) -> 4799 | U11: =$V11-($V11-$L11)*(1/10) -> 4829 | V11: 4859 | W11: =$AF11-($AF11-$V11)*(9/10) -> 4820.1 | X11: =$AF11-($AF11-$V11)*(8/10) -> 4781.2 | Y11: =$AF11-($AF11-$V11)*(7/10) -> 4742.3 | Z11: =$AF11-($AF11-$V11)*(6/10) -> 4703.4 | AA11: =$AF11-($AF11-$V11)*(5/10) -> 4664.5 | AB11: =$AF11-($AF11-$V11)*(4/10) -> 4625.6 | AC11: =$AF11-($AF11-$V11)*(3/10) -> 4586.7 | AD11: =$AF11-($AF11-$V11)*(2/10) -> 4547.8 | AE11: =$AF11-($AF11-$V11)*(1/10) -> 4508.9 | AF11: 4470 | AG11: =$AP11-($AP11-$AF11)*(9/10) -> 4445.8 | AH11: =$AP11-($AP11-$AF11)*(8/10) -> 4421.6 | AI11: =$AP11-($AP11-$AF11)*(7/10) -> 4397.4 | AJ11: =$AP11-($AP11-$AF11)*(6/10) -> 4373.2 | AK11: =$AP11-($AP11-$AF11)*(5/10) -> 4349 | AL11: =$AP11-($AP11-$AF11)*(4/10) -> 4324.8 | AM11: =$AP11-($AP11-$AF11)*(3/10) -> 4300.6 | AN11: =$AP11-($AP11-$AF11)*(2/10) -> 4276.4 | AO11: =$AP11-($AP11-$AF11)*(1/10) -> 4252.2 | AP11: 4228 | AQ11: =AP11*(1+((AP11/AO11)-1)) -> 4203.9377 | AR11: =AQ11*(1+((AQ11/AP11)-1)) -> 4180.0124 | AS11: =AR11*(1+((AR11/AQ11)-1)) -> 4156.2232 | AT11: =AS11*(1+((AS11/AR11)-1)) -> 4132.5694 | AU11: =AT11*(1+((AT11/AS11)-1)) -> 4109.0503 | AV11: =AU11*(1+((AU11/AT11)-1)) -> 4085.665 | AW11: =AV11*(1+((AV11/AU11)-1)) -> 4062.4128 | AX11: =AW11*(1+((AW11/AV11)-1)) -> 4039.2929 | AY11: =AX11*(1+((AX11/AW11)-1)) -> 4016.3046
A12: Dunedin | B12: 108734 | C12: =$L12-($L12-$B12)*(9/10) -> 109182.8 | D12: =$L12-($L12-$B12)*(8/10) -> 109631.6 | E12: =$L12-($L12-$B12)*(7/10) -> 110080.4 | F12: =$L12-($L12-$B12)*(6/10) -> 110529.2 | G12: =$L12-($L12-$B12)*(5/10) -> 110978 | H12: =$L12-($L12-$B12)*(4/10) -> 111426.8 | I12: =$L12-($L12-$B12)*(3/10) -> 111875.6 | J12: =$L12-($L12-$B12)*(2/10) -> 112324.4 | K12: =$L12-($L12-$B12)*(1/10) -> 112773.2 | L12: 113222 | M12: =$V12-($V12-$L12)*(9/10) -> 112786.2 | N12: =$V12-($V12-$L12)*(8/10) -> 112350.4 | O12: =$V12-($V12-$L12)*(7/10) -> 111914.6 | P12: =$V12-($V12-$L12)*(6/10) -> 111478.8 | Q12: =$V12-($V12-$L12)*(5/10) -> 111043 | R12: =$V12-($V12-$L12)*(4/10) -> 110607.2 | S12: =$V12-($V12-$L12)*(3/10) -> 110171.4 | T12: =$V12-($V12-$L12)*(2/10) -> 109735.6 | U12: =$V12-($V12-$L12)*(1/10) -> 109299.8 | V12: 108864 | W12: =$AF12-($AF12-$V12)*(9/10) -> 109205.5 | X12: =$AF12-($AF12-$V12)*(8/10) -> 109547 | Y12: =$AF12-($AF12-$V12)*(7/10) -> 109888.5 | Z12: =$AF12-($AF12-$V12)*(6/10) -> 110230 | AA12: =$AF12-($AF12-$V12)*(5/10) -> 110571.5 | AB12: =$AF12-($AF12-$V12)*(4/10) -> 110913 | AC12: =$AF12-($AF12-$V12)*(3/10) -> 111254.5 | AD12: =$AF12-($AF12-$V12)*(2/10) -> 111596 | AE12: =$AF12-($AF12-$V12)*(1/10) -> 111937.5 | AF12: 112279 | AG12: =$AP12-($AP12-$AF12)*(9/10) -> 112150.8 | AH12: =$AP12-($AP12-$AF12)*(8/10) -> 112022.6 | AI12: =$AP12-($AP12-$AF12)*(7/10) -> 111894.4 | AJ12: =$AP12-($AP12-$AF12)*(6/10) -> 111766.2 | AK12: =$AP12-($AP12-$AF12)*(5/10) -> 111638 | AL12: =$AP12-($AP12-$AF12)*(4/10) -> 111509.8 | AM12: =$AP12-($AP12-$AF12)*(3/10) -> 111381.6 | AN12: =$AP12-($AP12-$AF12)*(2/10) -> 111253.4 | AO12: =$AP12-($AP12-$AF12)*(1/10) -> 111125.2 | AP12: 110997 | AQ12: =AP12*(1+((AP12/AO12)-1)) -> 110868.95 | AR12: =AQ12*(1+((AQ12/AP12)-1)) -> 110741.04 | AS12: =AR12*(1+((AR12/AQ12)-1)) -> 110613.29 | AT12: =AS12*(1+((AS12/AR12)-1)) -> 110485.68 | AU12: =AT12*(1+((AT12/AS12)-1)) -> 110358.22 | AV12: =AU12*(1+((AU12/AT12)-1)) -> 110230.9 | AW12: =AV12*(1+((AV12/AU12)-1)) -> 110103.73 | AX12: =AW12*(1+((AW12/AV12)-1)) -> 109976.71 | AY12: =AX12*(1+((AX12/AW12)-1)) -> 109849.83
A13: Eltham | B13: 2319 | C13: =$L13-($L13-$B13)*(9/10) -> 2320.5 | D13: =$L13-($L13-$B13)*(8/10) -> 2322 | E13: =$L13-($L13-$B13)*(7/10) -> 2323.5 | F13: =$L13-($L13-$B13)*(6/10) -> 2325 | G13: =$L13-($L13-$B13)*(5/10) -> 2326.5 | H13: =$L13-($L13-$B13)*(4/10) -> 2328 | I13: =$L13-($L13-$B13)*(3/10) -> 2329.5 | J13: =$L13-($L13-$B13)*(2/10) -> 2331 | K13: =$L13-($L13-$B13)*(1/10) -> 2332.5 | L13: 2334 | M13: =$V13-($V13-$L13)*(9/10) -> 2329.4 | N13: =$V13-($V13-$L13)*(8/10) -> 2324.8 | O13: =$V13-($V13-$L13)*(7/10) -> 2320.2 | P13: =$V13-($V13-$L13)*(6/10) -> 2315.6 | Q13: =$V13-($V13-$L13)*(5/10) -> 2311 | R13: =$V13-($V13-$L13)*(4/10) -> 2306.4 | S13: =$V13-($V13-$L13)*(3/10) -> 2301.8 | T13: =$V13-($V13-$L13)*(2/10) -> 2297.2 | U13: =$V13-($V13-$L13)*(1/10) -> 2292.6 | V13: 2288 | W13: =$AF13-($AF13-$V13)*(9/10) -> 2244.3 | X13: =$AF13-($AF13-$V13)*(8/10) -> 2200.6 | Y13: =$AF13-($AF13-$V13)*(7/10) -> 2156.9 | Z13: =$AF13-($AF13-$V13)*(6/10) -> 2113.2 | AA13: =$AF13-($AF13-$V13)*(5/10) -> 2069.5 | AB13: =$AF13-($AF13-$V13)*(4/10) -> 2025.8 | AC13: =$AF13-($AF13-$V13)*(3/10) -> 1982.1 | AD13: =$AF13-($AF13-$V13)*(2/10) -> 1938.4 | AE13: =$AF13-($AF13-$V13)*(1/10) -> 1894.7 | AF13: 1851 | AG13: =$AP13-($AP13-$AF13)*(9/10) -> 1833.7 | AH13: =$AP13-($AP13-$AF13)*(8/10) -> 1816.4 | AI13: =$AP13-($AP13-$AF13)*(7/10) -> 1799.1 | AJ13: =$AP13-($AP13-$AF13)*(6/10) -> 1781.8 | AK13: =$AP13-($AP13-$AF13)*(5/10) -> 1764.5 | AL13: =$AP13-($AP13-$AF13)*(4/10) -> 1747.2 | AM13: =$AP13-($AP13-$AF13)*(3/10) -> 1729.9 | AN13: =$AP13-($AP13-$AF13)*(2/10) -> 1712.6 | AO13: =$AP13-($AP13-$AF13)*(1/10) -> 1695.3 | AP13: 1678 | AQ13: =AP13*(1+((AP13/AO13)-1)) -> 1660.8765 | AR13: =AQ13*(1+((AQ13/AP13)-1)) -> 1643.9278 | AS13: =AR13*(1+((AR13/AQ13)-1)) -> 1627.1521 | AT13: =AS13*(1+((AS13/AR13)-1)) -> 1610.5475 | AU13: =AT13*(1+((AT13/AS13)-1)) -> 1594.1124 | AV13: =AU13*(1+((AU13/AT13)-1)) -> 1577.8449 | AW13: =AV13*(1+((AV13/AU13)-1)) -> 1561.7435 | AX13: =AW13*(1+((AW13/AV13)-1)) -> 1545.8064 | AY13: =AX13*(1+((AX13/AW13)-1)) -> 1530.032
... A25: Kaitangata | B25: 1208 | C25: =$L25-($L25-$B25)*(9/10) -> 1199.2 | D25: =$L25-($L25-$B25)*(8/10) -> 1190.4 | E25: =$L25-($L25-$B25)*(7/10) -> 1181.6 | F25: =$L25-($L25-$B25)*(6/10) -> 1172.8 | G25: =$L25-($L25-$B25)*(5/10) -> 1164 | H25: =$L25-($L25-$B25)*(4/10) -> 1155.2 | I25: =$L25-($L25-$B25)*(3/10) -> 1146.4 | J25: =$L25-($L25-$B25)*(2/10) -> 1137.6 | K25: =$L25-($L25-$B25)*(1/10) -> 1128.8 | L25: 1120 | M25: =$V25-($V25-$L25)*(9/10) -> 1105.2 | N25: =$V25-($V25-$L25)*(8/10) -> 1090.4 | O25: =$V25-($V25-$L25)*(7/10) -> 1075.6 | P25: =$V25-($V25-$L25)*(6/10) -> 1060.8 | Q25: =$V25-($V25-$L25)*(5/10) -> 1046 | R25: =$V25-($V25-$L25)*(4/10) -> 1031.2 | S25: =$V25-($V25-$L25)*(3/10) -> 1016.4 | T25: =$V25-($V25-$L25)*(2/10) -> 1001.6 | U25: =$V25-($V25-$L25)*(1/10) -> 986.8 | V25: 972 | W25: =$AF25-($AF25-$V25)*(9/10) -> 962 | X25: =$AF25-($AF25-$V25)*(8/10) -> 952 | Y25: =$AF25-($AF25-$V25)*(7/10) -> 942 | Z25: =$AF25-($AF25-$V25)*(6/10) -> 932 | AA25: =$AF25-($AF25-$V25)*(5/10) -> 922 | AB25: =$AF25-($AF25-$V25)*(4/10) -> 912 | AC25: =$AF25-($AF25-$V25)*(3/10) -> 902 | AD25: =$AF25-($AF25-$V25)*(2/10) -> 892 | AE25: =$AF25-($AF25-$V25)*(1/10) -> 882 | AF25: 872 | AG25: =$AP25-($AP25-$AF25)*(9/10) -> 864.2 | AH25: =$AP25-($AP25-$AF25)*(8/10) -> 856.4 | AI25: =$AP25-($AP25-$AF25)*(7/10) -> 848.6 | AJ25: =$AP25-($AP25-$AF25)*(6/10) -> 840.8 | AK25: =$AP25-($AP25-$AF25)*(5/10) -> 833 | AL25: =$AP25-($AP25-$AF25)*(4/10) -> 825.2 | AM25: =$AP25-($AP25-$AF25)*(3/10) -> 817.4 | AN25: =$AP25-($AP25-$AF25)*(2/10) -> 809.6 | AO25: =$AP25-($AP25-$AF25)*(1/10) -> 801.8 | AP25: 794 | AQ25: =AP25*(1+((AP25/AO25)-1)) -> 786.27588 | AR25: =AQ25*(1+((AQ25/AP25)-1)) -> 778.6269 | AS25: =AR25*(1+((AR25/AQ25)-1)) -> 771.05233 | AT25: =AS25*(1+((AS25/AR25)-1)) -> 763.55145 | AU25: =AT25*(1+((AT25/AS25)-1)) -> 756.12353 | AV25: =AU25*(1+((AU25/AT25)-1)) -> 748.76788 | AW25: =AV25*(1+((AV25/AU25)-1)) -> 741.48378 | AX25: =AW25*(1+((AW25/AV25)-1)) -> 734.27054 | AY25: =AX25*(1+((AX25/AW25)-1)) -> 727.12748
A26: Kapiti | B26: =C26/(1+((D26/C26)-1)) -> 8768.5104 | C26: =D26/(1+((E26/D26)-1)) -> 9250.4768 | D26: =E26/(1+((F26/E26)-1)) -> 9758.9349 | E26: =F26/(1+((G26/F26)-1)) -> 10295.341 | F26: =G26/(1+((H26/G26)-1)) -> 10861.23 | G26: =H26/(1+((I26/H26)-1)) -> 11458.224 | H26: =I26/(1+((J26/I26)-1)) -> 12088.033 | I26: =J26/(1+((K26/J26)-1)) -> 12752.459 | ... K26: =L26/(1+((M26/L26)-1)) -> 14192.88 | L26: 14973 | M26: =$V26-($V26-$L26)*(9/10) -> 15796 | N26: =$V26-($V26-$L26)*(8/10) -> 16619 | O26: =$V26-($V26-$L26)*(7/10) -> 17442 | P26: =$V26-($V26-$L26)*(6/10) -> 18265 | Q26: =$V26-($V26-$L26)*(5/10) -> 19088 | R26: =$V26-($V26-$L26)*(4/10) -> 19911 | S26: =$V26-($V26-$L26)*(3/10) -> 20734 | T26: =$V26-($V26-$L26)*(2/10) -> 21557 | U26: =$V26-($V26-$L26)*(1/10) -> 22380 | V26: 23203 | W26: =$AF26-($AF26-$V26)*(9/10) -> 23883.1 | X26: =$AF26-($AF26-$V26)*(8/10) -> 24563.2 | Y26: =$AF26-($AF26-$V26)*(7/10) -> 25243.3 | Z26: =$AF26-($AF26-$V26)*(6/10) -> 25923.4 | AA26: =$AF26-($AF26-$V26)*(5/10) -> 26603.5 | AB26: =$AF26-($AF26-$V26)*(4/10) -> 27283.6 | AC26: =$AF26-($AF26-$V26)*(3/10) -> 27963.7 | AD26: =$AF26-($AF26-$V26)*(2/10) -> 28643.8 | AE26: =$AF26-($AF26-$V26)*(1/10) -> 29323.9 | AF26: 30004 | AG26: =$AP26-($AP26-$AF26)*(9/10) -> 30738.3 | AH26: =$AP26-($AP26-$AF26)*(8/10) -> 31472.6 | AI26: =$AP26-($AP26-$AF26)*(7/10) -> 32206.9 | AJ26: =$AP26-($AP26-$AF26)*(6/10) -> 32941.2 | AK26: =$AP26-($AP26-$AF26)*(5/10) -> 33675.5 | AL26: =$AP26-($AP26-$AF26)*(4/10) -> 34409.8 | AM26: =$AP26-($AP26-$AF26)*(3/10) -> 35144.1 | AN26: =$AP26-($AP26-$AF26)*(2/10) -> 35878.4 | AO26: =$AP26-($AP26-$AF26)*(1/10) -> 36612.7 | AP26: 37347 | AQ26: =AP26*(1+((AP26/AO26)-1)) -> 38096.027 | AR26: =AQ26*(1+((AQ26/AP26)-1)) -> 38860.076 | AS26: =AR26*(1+((AR26/AQ26)-1)) -> 39639.45 | AT26: =AS26*(1+((AS26/AR26)-1)) -> 40434.454 | AU26: =AT26*(1+((AT26/AS26)-1)) -> 41245.402 | AV26: =AU26*(1+((AU26/AT26)-1)) -> 42072.615 | AW26: =AV26*(1+((AV26/AU26)-1)) -> 42916.419 | AX26: =AW26*(1+((AW26/AV26)-1)) -> 43777.145 | AY26: =AX26*(1+((AX26/AW26)-1)) -> 44655.135
A27: Levin | B27: 14069 | C27: =$L27-($L27-$B27)*(9/10) -> 14483.2 | D27: =$L27-($L27-$B27)*(8/10) -> 14897.4 | E27: =$L27-($L27-$B27)*(7/10) -> 15311.6 | F27: =$L27-($L27-$B27)*(6/10) -> 15725.8 | G27: =$L27-($L27-$B27)*(5/10) -> 16140 | H27: =$L27-($L27-$B27)*(4/10) -> 16554.2 | I27: =$L27-($L27-$B27)*(3/10) -> 16968.4 | J27: =$L27-($L27-$B27)*(2/10) -> 17382.6 | K27: =$L27-($L27-$B27)*(1/10) -> 17796.8 | L27: 18211 | M27: =$V27-($V27-$L27)*(9/10) -> 18286.1 | N27: =$V27-($V27-$L27)*(8/10) -> 18361.2 | O27: =$V27-($V27-$L27)*(7/10) -> 18436.3 | P27: =$V27-($V27-$L27)*(6/10) -> 18511.4 | Q27: =$V27-($V27-$L27)*(5/10) -> 18586.5 | R27: =$V27-($V27-$L27)*(4/10) -> 18661.6 | S27: =$V27-($V27-$L27)*(3/10) -> 18736.7 | T27: =$V27-($V27-$L27)*(2/10) -> 18811.8 | U27: =$V27-($V27-$L27)*(1/10) -> 18886.9 | V27: 18962 | W27: =$AF27-($AF27-$V27)*(9/10) -> 19001.6 | X27: =$AF27-($AF27-$V27)*(8/10) -> 19041.2 | Y27: =$AF27-($AF27-$V27)*(7/10) -> 19080.8 | Z27: =$AF27-($AF27-$V27)*(6/10) -> 19120.4 | AA27: =$AF27-($AF27-$V27)*(5/10) -> 19160 | AB27: =$AF27-($AF27-$V27)*(4/10) -> 19199.6 | AC27: =$AF27-($AF27-$V27)*(3/10) -> 19239.2 | AD27: =$AF27-($AF27-$V27)*(2/10) -> 19278.8 | AE27: =$AF27-($AF27-$V27)*(1/10) -> 19318.4 | AF27: 19358 | AG27: =$AP27-($AP27-$AF27)*(9/10) -> 19339.4 | AH27: =$AP27-($AP27-$AF27)*(8/10) -> 19320.8 | AI27: =$AP27-($AP27-$AF27)*(7/10) -> 19302.2 | AJ27: =$AP27-($AP27-$AF27)*(6/10) -> 19283.6 | AK27: =$AP27-($AP27-$AF27)*(5/10) -> 19265 | AL27: =$AP27-($AP27-$AF27)*(4/10) -> 19246.4 | AM27: =$AP27-($AP27-$AF27)*(3/10) -> 19227.8 | AN27: =$AP27-($AP27-$AF27)*(2/10) -> 19209.2 | AO27: =$AP27-($AP27-$AF27)*(1/10) -> 19190.6 | AP27: 19172 | AQ27: =AP27*(1+((AP27/AO27)-1)) -> 19153.418 | AR27: =AQ27*(1+((AQ27/AP27)-1)) -> 19134.854 | AS27: =AR27*(1+((AR27/AQ27)-1)) -> 19116.308 | AT27: =AS27*(1+((AS27/AR27)-1)) -> 19097.78 | AU27: =AT27*(1+((AT27/AS27)-1)) -> 19079.27 | AV27: =AU27*(1+((AU27/AT27)-1)) -> 19060.778 | AW27: =AV27*(1+((AV27/AU27)-1)) -> 19042.304 | AX27: =AW27*(1+((AW27/AV27)-1)) -> 19023.848 | AY27: =AX27*(1+((AX27/AW27)-1)) -> 19005.409
A28: Marton | B28: 4731 | C28: =$L28-($L28-$B28)*(9/10) -> 4748.9 | D28: =$L28-($L28-$B28)*(8/10) -> 4766.8 | E28: =$L28-($L28-$B28)*(7/10) -> 4784.7 | F28: =$L28-($L28-$B28)*(6/10) -> 4802.6 | G28: =$L28-($L28-$B28)*(5/10) -> 4820.5 | H28: =$L28-($L28-$B28)*(4/10) -> 4838.4 | I28: =$L28-($L28-$B28)*(3/10) -> 4856.3 | J28: =$L28-($L28-$B28)*(2/10) -> 4874.2 | K28: =$L28-($L28-$B28)*(1/10) -> 4892.1 | L28: 4910 | M28: =$V28-($V28-$L28)*(9/10) -> 4924.9 | N28: =$V28-($V28-$L28)*(8/10) -> 4939.8 | O28: =$V28-($V28-$L28)*(7/10) -> 4954.7 | P28: =$V28-($V28-$L28)*(6/10) -> 4969.6 | Q28: =$V28-($V28-$L28)*(5/10) -> 4984.5 | R28: =$V28-($V28-$L28)*(4/10) -> 4999.4 | S28: =$V28-($V28-$L28)*(3/10) -> 5014.3 | T28: =$V28-($V28-$L28)*(2/10) -> 5029.2 | U28: =$V28-($V28-$L28)*(1/10) -> 5044.1 | V28: 5059 | W28: =$AF28-($AF28-$V28)*(9/10) -> 5037.8 | X28: =$AF28-($AF28-$V28)*(8/10) -> 5016.6 | Y28: =$AF28-($AF28-$V28)*(7/10) -> 4995.4 | Z28: =$AF28-($AF28-$V28)*(6/10) -> 4974.2 | AA28: =$AF28-($AF28-$V28)*(5/10) -> 4953 | AB28: =$AF28-($AF28-$V28)*(4/10) -> 4931.8 | AC28: =$AF28-($AF28-$V28)*(3/10) -> 4910.6 | AD28: =$AF28-($AF28-$V28)*(2/10) -> 4889.4 | AE28: =$AF28-($AF28-$V28)*(1/10) -> 4868.2 | AF28: 4847 | AG28: =$AP28-($AP28-$AF28)*(9/10) -> 4784.9 | AH28: =$AP28-($AP28-$AF28)*(8/10) -> 4722.8 | AI28: =$AP28-($AP28-$AF28)*(7/10) -> 4660.7 | AJ28: =$AP28-($AP28-$AF28)*(6/10) -> 4598.6 | AK28: =$AP28-($AP28-$AF28)*(5/10) -> 4536.5 | AL28: =$AP28-($AP28-$AF28)*(4/10) -> 4474.4 | AM28: =$AP28-($AP28-$AF28)*(3/10) -> 4412.3 | AN28: =$AP28-($AP28-$AF28)*(2/10) -> 4350.2 | AO28: =$AP28-($AP28-$AF28)*(1/10) -> 4288.1 | AP28: 4226 | AQ28: =AP28*(1+((AP28/AO28)-1)) -> 4164.7993 | AR28: =AQ28*(1+((AQ28/AP28)-1)) -> 4104.485 | AS28: =AR28*(1+((AR28/AQ28)-1)) -> 4045.0441 | AT28: =AS28*(1+((AS28/AR28)-1)) -> 3986.464 | AU28: =AT28*(1+((AT28/AS28)-1)) -> 3928.7323 | AV28: =AU28*(1+((AU28/AT28)-1)) -> 3871.8366 | AW28: =AV28*(1+((AV28/AU28)-1)) -> 3815.7649 | AX28: =AW28*(1+((AW28/AV28)-1)) -> 3760.5052 | AY28: =AX28*(1+((AX28/AW28)-1)) -> 3706.0458
A29: Masterton | B29: 17596 | C29: =$L29-($L29-$B29)*(9/10) -> 17936.5 | D29: =$L29-($L29-$B29)*(8/10) -> 18277 | E29: =$L29-($L29-$B29)*(7/10) -> 18617.5 | F29: =$L29-($L29-$B29)*(6/10) -> 18958 | G29: =$L29-($L29-$B29)*(5/10) -> 19298.5 | H29: =$L29-($L29-$B29)*(4/10) -> 19639 | I29: =$L29-($L29-$B29)*(3/10) -> 19979.5 | J29: =$L29-($L29-$B29)*(2/10) -> 20320 | K29: =$L29-($L29-$B29)*(1/10) -> 20660.5 | L29: 21001 | M29: =$V29-($V29-$L29)*(9/10) -> 20836.2 | N29: =$V29-($V29-$L29)*(8/10) -> 20671.4 | O29: =$V29-($V29-$L29)*(7/10) -> 20506.6 | P29: =$V29-($V29-$L29)*(6/10) -> 20341.8 | Q29: =$V29-($V29-$L29)*(5/10) -> 20177 | R29: =$V29-($V29-$L29)*(4/10) -> 20012.2 | S29: =$V29-($V29-$L29)*(3/10) -> 19847.4 | T29: =$V29-($V29-$L29)*(2/10) -> 19682.6 | U29: =$V29-($V29-$L29)*(1/10) -> 19517.8 | V29: 19353 | W29: =$AF29-($AF29-$V29)*(9/10) -> 19386.3 | X29: =$AF29-($AF29-$V29)*(8/10) -> 19419.6 | Y29: =$AF29-($AF29-$V29)*(7/10) -> 19452.9 | Z29: =$AF29-($AF29-$V29)*(6/10) -> 19486.2 | AA29: =$AF29-($AF29-$V29)*(5/10) -> 19519.5 | AB29: =$AF29-($AF29-$V29)*(4/10) -> 19552.8 | AC29: =$AF29-($AF29-$V29)*(3/10) -> 19586.1 | AD29: =$AF29-($AF29-$V29)*(2/10) -> 19619.4 | AE29: =$AF29-($AF29-$V29)*(1/10) -> 19652.7 | AF29: 19686 | AG29: =$AP29-($AP29-$AF29)*(9/10) -> 19667.1 | AH29: =$AP29-($AP29-$AF29)*(8/10) -> 19648.2 | AI29: =$AP29-($AP29-$AF29)*(7/10) -> 19629.3 | AJ29: =$AP29-($AP29-$AF29)*(6/10) -> 19610.4 | AK29: =$AP29-($AP29-$AF29)*(5/10) -> 19591.5 | AL29: =$AP29-($AP29-$AF29)*(4/10) -> 19572.6 | AM29: =$AP29-($AP29-$AF29)*(3/10) -> 19553.7 | AN29: =$AP29-($AP29-$AF29)*(2/10) -> 19534.8 | AO29: =$AP29-($AP29-$AF29)*(1/10) -> 19515.9 | AP29: 19497 | AQ29: =AP29*(1+((AP29/AO29)-1)) -> 19478.118 | AR29: =AQ29*(1+((AQ29/AP29)-1)) -> 19459.255 | AS29: =AR29*(1+((AR29/AQ29)-1)) -> 19440.41 | AT29: =AS29*(1+((AS29/AR29)-1)) -> 19421.583 | AU29: =AT29*(1+((AT29/AS29)-1)) -> 19402.774 | AV29: =AU29*(1+((AU29/AT29)-1)) -> 19383.984 | AW29: =AV29*(1+((AV29/AU29)-1)) -> 19365.212 | AX29: =AW29*(1+((AW29/AV29)-1)) -> 19346.457 | AY29: =AX29*(1+((AX29/AW29)-1)) -> 19327.722
A30: Milton | B30: 1861 | C30: =$L30-($L30-$B30)*(9/10) -> 1896.7 | D30: =$L30-($L30-$B30)*(8/10) -> 1932.4 | E30: =$L30-($L30-$B30)*(7/10) -> 1968.1 | F30: =$L30-($L30-$B30)*(6/10) -> 2003.8 | G30: =$L30-($L30-$B30)*(5/10) -> 2039.5 | H30: =$L30-($L30-$B30)*(4/10) -> 2075.2 | I30: =$L30-($L30-$B30)*(3/10) -> 2110.9 | J30: =$L30-($L30-$B30)*(2/10) -> 2146.6 | K30: =$L30-($L30-$B30)*(1/10) -> 2182.3 | L30: 2218 | M30: =$V30-($V30-$L30)*(9/10) -> 2211.6 | N30: =$V30-($V30-$L30)*(8/10) -> 2205.2 | O30: =$V30-($V30-$L30)*(7/10) -> 2198.8 | P30: =$V30-($V30-$L30)*(6/10) -> 2192.4 | Q30: =$V30-($V30-$L30)*(5/10) -> 2186 | R30: =$V30-($V30-$L30)*(4/10) -> 2179.6 | S30: =$V30-($V30-$L30)*(3/10) -> 2173.2 | T30: =$V30-($V30-$L30)*(2/10) -> 2166.8 | U30: =$V30-($V30-$L30)*(1/10) -> 2160.4 | V30: 2154 | W30: =$AF30-($AF30-$V30)*(9/10) -> 2132.6 | X30: =$AF30-($AF30-$V30)*(8/10) -> 2111.2 | Y30: =$AF30-($AF30-$V30)*(7/10) -> 2089.8 | Z30: =$AF30-($AF30-$V30)*(6/10) -> 2068.4 | AA30: =$AF30-($AF30-$V30)*(5/10) -> 2047 | AB30: =$AF30-($AF30-$V30)*(4/10) -> 2025.6 | AC30: =$AF30-($AF30-$V30)*(3/10) -> 2004.2 | AD30: =$AF30-($AF30-$V30)*(2/10) -> 1982.8 | AE30: =$AF30-($AF30-$V30)*(1/10) -> 1961.4 | AF30: 1940 | AG30: =$AP30-($AP30-$AF30)*(9/10) -> 1922 | AH30: =$AP30-($AP30-$AF30)*(8/10) -> 1904 | AI30: =$AP30-($AP30-$AF30)*(7/10) -> 1886 | AJ30: =$AP30-($AP30-$AF30)*(6/10) -> 1868 | AK30: =$AP30-($AP30-$AF30)*(5/10) -> 1850 | AL30: =$AP30-($AP30-$AF30)*(4/10) -> 1832 | AM30: =$AP30-($AP30-$AF30)*(3/10) -> 1814 | AN30: =$AP30-($AP30-$AF30)*(2/10) -> 1796 | AO30: =$AP30-($AP30-$AF30)*(1/10) -> 1778 | AP30: 1760 | AQ30: =AP30*(1+((AP30/AO30)-1)) -> 1742.1822 | AR30: =AQ30*(1+((AQ30/AP30)-1)) -> 1724.5448 | AS30: =AR30*(1+((AR30/AQ30)-1)) -> 1707.086 | AT30: =AS30*(1+((AS30/AR30)-1)) -> 1689.8039 | AU30: =AT30*(1+((AT30/AS30)-1)) -> 1672.6968 | AV30: =AU30*(1+((AU30/AT30)-1)) -> 1655.7629 | AW30: =AV30*(1+((AV30/AU30)-1)) -> 1639.0003 | AX30: =AW30*(1+((AW30/AV30)-1)) -> 1622.4075 | AY30: =AX30*(1+((AX30/AW30)-1)) -> 1605.9827
A31: Morrinsville | B31: 4497 | C31: =$L31-($L31-$B31)*(9/10) -> 4525.6 | D31: =$L31-($L31-$B31)*(8/10) -> 4554.2 | E31: =$L31-($L31-$B31)*(7/10) -> 4582.8 | F31: =$L31-($L31-$B31)*(6/10) -> 4611.4 | G31: =$L31-($L31-$B31)*(5/10) -> 4640 | H31: =$L31-($L31-$B31)*(4/10) -> 4668.6 | I31: =$L31-($L31-$B31)*(3/10) -> 4697.2 | J31: =$L31-($L31-$B31)*(2/10) -> 4725.8 | K31: =$L31-($L31-$B31)*(1/10) -> 4754.4 | L31: 4783 | M31: =$V31-($V31-$L31)*(9/10) -> 4832.8 | N31: =$V31-($V31-$L31)*(8/10) -> 4882.6 | O31: =$V31-($V31-$L31)*(7/10) -> 4932.4 | P31: =$V31-($V31-$L31)*(6/10) -> 4982.2 | Q31: =$V31-($V31-$L31)*(5/10) -> 5032 | R31: =$V31-($V31-$L31)*(4/10) -> 5081.8 | S31: =$V31-($V31-$L31)*(3/10) -> 5131.6 | T31: =$V31-($V31-$L31)*(2/10) -> 5181.4 | U31: =$V31-($V31-$L31)*(1/10) -> 5231.2 | V31: 5281 | W31: =$AF31-($AF31-$V31)*(9/10) -> 5319.6 | X31: =$AF31-($AF31-$V31)*(8/10) -> 5358.2 | Y31: =$AF31-($AF31-$V31)*(7/10) -> 5396.8 | Z31: =$AF31-($AF31-$V31)*(6/10) -> 5435.4 | AA31: =$AF31-($AF31-$V31)*(5/10) -> 5474 | AB31: =$AF31-($AF31-$V31)*(4/10) -> 5512.6 | AC31: =$AF31-($AF31-$V31)*(3/10) -> 5551.2 | AD31: =$AF31-($AF31-$V31)*(2/10) -> 5589.8 | AE31: =$AF31-($AF31-$V31)*(1/10) -> 5628.4 | AF31: 5667 | AG31: =$AP31-($AP31-$AF31)*(9/10) -> 5708.6 | AH31: =$AP31-($AP31-$AF31)*(8/10) -> 5750.2 | AI31: =$AP31-($AP31-$AF31)*(7/10) -> 5791.8 | AJ31: =$AP31-($AP31-$AF31)*(6/10) -> 5833.4 | AK31: =$AP31-($AP31-$AF31)*(5/10) -> 5875 | AL31: =$AP31-($AP31-$AF31)*(4/10) -> 5916.6 | AM31: =$AP31-($AP31-$AF31)*(3/10) -> 5958.2 | AN31: =$AP31-($AP31-$AF31)*(2/10) -> 5999.8 | AO31: =$AP31-($AP31-$AF31)*(1/10) -> 6041.4 | AP31: 6083 | AQ31: =AP31*(1+((AP31/AO31)-1)) -> 6124.8865 | AR31: =AQ31*(1+((AQ31/AP31)-1)) -> 6167.0613 | AS31: =AR31*(1+((AR31/AQ31)-1)) -> 6209.5266 | AT31: =AS31*(1+((AS31/AR31)-1)) -> 6252.2843 | AU31: =AT31*(1+((AT31/AS31)-1)) -> 6295.3364 | AV31: =AU31*(1+((AU31/AT31)-1)) -> 6338.685 | AW31: =AV31*(1+((AV31/AU31)-1)) -> 6382.332 | AX31: =AW31*(1+((AW31/AV31)-1)) -> 6426.2796 | AY31: =AX31*(1+((AX31/AW31)-1)) -> 6470.5298
A32: Napier | B32: 38309 | C32: =$L32-($L32-$B32)*(9/10) -> 39494.5 | D32: =$L32-($L32-$B32)*(8/10) -> 40680 | E32: =$L32-($L32-$B32)*(7/10) -> 41865.5 | F32: =$L32-($L32-$B32)*(6/10) -> 43051 | G32: =$L32-($L32-$B32)*(5/10) -> 44236.5 | H32: =$L32-($L32-$B32)*(4/10) -> 45422 | I32: =$L32-($L32-$B32)*(3/10) -> 46607.5 | J32: =$L32-($L32-$B32)*(2/10) -> 47793 | K32: =$L32-($L32-$B32)*(1/10) -> 48978.5 | L32: 50164 | M32: =$V32-($V32-$L32)*(9/10) -> 50362.7 | N32: =$V32-($V32-$L32)*(8/10) -> 50561.4 | O32: =$V32-($V32-$L32)*(7/10) -> 50760.1 | P32: =$V32-($V32-$L32)*(6/10) -> 50958.8 | Q32: =$V32-($V32-$L32)*(5/10) -> 51157.5 | R32: =$V32-($V32-$L32)*(4/10) -> 51356.2 | S32: =$V32-($V32-$L32)*(3/10) -> 51554.9 | T32: =$V32-($V32-$L32)*(2/10) -> 51753.6 | U32: =$V32-($V32-$L32)*(1/10) -> 51952.3 | V32: 52151 | W32: =$AF32-($AF32-$V32)*(9/10) -> 52440.3 | X32: =$AF32-($AF32-$V32)*(8/10) -> 52729.6 | Y32: =$AF32-($AF32-$V32)*(7/10) -> 53018.9 | Z32: =$AF32-($AF32-$V32)*(6/10) -> 53308.2 | AA32: =$AF32-($AF32-$V32)*(5/10) -> 53597.5 | AB32: =$AF32-($AF32-$V32)*(4/10) -> 53886.8 | AC32: =$AF32-($AF32-$V32)*(3/10) -> 54176.1 | AD32: =$AF32-($AF32-$V32)*(2/10) -> 54465.4 | AE32: =$AF32-($AF32-$V32)*(1/10) -> 54754.7 | AF32: 55044 | AG32: =$AP32-($AP32-$AF32)*(9/10) -> 55168.2 | AH32: =$AP32-($AP32-$AF32)*(8/10) -> 55292.4 | AI32: =$AP32-($AP32-$AF32)*(7/10) -> 55416.6 | AJ32: =$AP32-($AP32-$AF32)*(6/10) -> 55540.8 | AK32: =$AP32-($AP32-$AF32)*(5/10) -> 55665 | AL32: =$AP32-($AP32-$AF32)*(4/10) -> 55789.2 | AM32: =$AP32-($AP32-$AF32)*(3/10) -> 55913.4 | AN32: =$AP32-($AP32-$AF32)*(2/10) -> 56037.6 | AO32: =$AP32-($AP32-$AF32)*(1/10) -> 56161.8 | AP32: 56286 | AQ32: =AP32*(1+((AP32/AO32)-1)) -> 56410.475 | AR32: =AQ32*(1+((AQ32/AP32)-1)) -> 56535.225 | AS32: =AR32*(1+((AR32/AQ32)-1)) -> 56660.25 | AT32: =AS32*(1+((AS32/AR32)-1)) -> 56785.553 | AU32: =AT32*(1+((AT32/AS32)-1)) -> 56911.132 | AV32: =AU32*(1+((AU32/AT32)-1)) -> 57036.989 | AW32: =AV32*(1+((AV32/AU32)-1)) -> 57163.125 | AX32: =AW32*(1+((AW32/AV32)-1)) -> 57289.539 | AY32: =AX32*(1+((AX32/AW32)-1)) -> 57416.233
A33: Nelson | B33: 27615 | C33: =$L33-($L33-$B33)*(9/10) -> 29096.8 | D33: =$L33-($L33-$B33)*(8/10) -> 30578.6 | E33: =$L33-($L33-$B33)*(7/10) -> 32060.4 | F33: =$L33-($L33-$B33)*(6/10) -> 33542.2 | G33: =$L33-($L33-$B33)*(5/10) -> 35024 | H33: =$L33-($L33-$B33)*(4/10) -> 36505.8 | I33: =$L33-($L33-$B33)*(3/10) -> 37987.6 | J33: =$L33-($L33-$B33)*(2/10) -> 39469.4 | K33: =$L33-($L33-$B33)*(1/10) -> 40951.2 | L33: 42433 | M33: =$V33-($V33-$L33)*(9/10) -> 42649 | N33: =$V33-($V33-$L33)*(8/10) -> 42865 | O33: =$V33-($V33-$L33)*(7/10) -> 43081 | P33: =$V33-($V33-$L33)*(6/10) -> 43297 | Q33: =$V33-($V33-$L33)*(5/10) -> 43513 | R33: =$V33-($V33-$L33)*(4/10) -> 43729 | S33: =$V33-($V33-$L33)*(3/10) -> 43945 | T33: =$V33-($V33-$L33)*(2/10) -> 44161 | U33: =$V33-($V33-$L33)*(1/10) -> 44377 | V33: 44593 | W33: =$AF33-($AF33-$V33)*(9/10) -> 45202.8 | X33: =$AF33-($AF33-$V33)*(8/10) -> 45812.6 | Y33: =$AF33-($AF33-$V33)*(7/10) -> 46422.4 | Z33: =$AF33-($AF33-$V33)*(6/10) -> 47032.2 | AA33: =$AF33-($AF33-$V33)*(5/10) -> 47642 | AB33: =$AF33-($AF33-$V33)*(4/10) -> 48251.8 | AC33: =$AF33-($AF33-$V33)*(3/10) -> 48861.6 | AD33: =$AF33-($AF33-$V33)*(2/10) -> 49471.4 | AE33: =$AF33-($AF33-$V33)*(1/10) -> 50081.2 | AF33: 50691 | AG33: =$AP33-($AP33-$AF33)*(9/10) -> 51258.6 | AH33: =$AP33-($AP33-$AF33)*(8/10) -> 51826.2 | AI33: =$AP33-($AP33-$AF33)*(7/10) -> 52393.8 | AJ33: =$AP33-($AP33-$AF33)*(6/10) -> 52961.4 | AK33: =$AP33-($AP33-$AF33)*(5/10) -> 53529 | AL33: =$AP33-($AP33-$AF33)*(4/10) -> 54096.6 | AM33: =$AP33-($AP33-$AF33)*(3/10) -> 54664.2 | AN33: =$AP33-($AP33-$AF33)*(2/10) -> 55231.8 | AO33: =$AP33-($AP33-$AF33)*(1/10) -> 55799.4 | AP33: 56367 | AQ33: =AP33*(1+((AP33/AO33)-1)) -> 56940.374 | AR33: =AQ33*(1+((AQ33/AP33)-1)) -> 57519.58 | AS33: =AR33*(1+((AR33/AQ33)-1)) -> 58104.678 | AT33: =AS33*(1+((AS33/AR33)-1)) -> 58695.727 | AU33: =AT33*(1+((AT33/AS33)-1)) -> 59292.789 | AV33: =AU33*(1+((AU33/AT33)-1)) -> 59895.925 | AW33: =AV33*(1+((AV33/AU33)-1)) -> 60505.195 | AX33: =AW33*(1+((AW33/AV33)-1)) -> 61120.663 | AY33: =AX33*(1+((AX33/AW33)-1)) -> 61742.392
